<mujoco model="atlas_skeleton">
    <compiler angle="radian" meshdir="meshes/" />
    <option>
        <flag contact="enable" gravity="disable" />
    </option>
    <size njmax="500" nconmax="100" />


    <default>
        <geom contype="4" conaffinity="1" condim="1" margin="0.001" />
        <position kp="1000" ctrllimited="true" ctrlrange="-1.57 1.57"/>

    </default>

        <contact>
        <pair geom1="l_dfarm" geom2="r_dfarm"/>
        <pair geom1="l_dfarm" geom2="r_ufarm"/>
        <pair geom1="l_dfarm" geom2="right_palm"/>
        <pair geom1="l_dfarm" geom2="r_uarm"/>
        <pair geom1="r_dfarm" geom2="l_ufarm"/>
        <pair geom1="r_dfarm" geom2="left_palm"/>
        <pair geom1="left_palm" geom2="l_uleg"/>
        <pair geom1="left_palm" geom2="l_lleg"/>
        <pair geom1="left_palm" geom2="r_uleg"/>
        <pair geom1="left_palm" geom2="r_lleg"/>
        <pair geom1="right_palm" geom2="l_uleg"/>
        <pair geom1="right_palm" geom2="l_lleg"/>
        <pair geom1="right_palm" geom2="r_uleg"/>
        <pair geom1="right_palm" geom2="r_lleg"/>

        <pair geom1="l_dfarm" geom2="l_uleg"/>
        <pair geom1="l_dfarm" geom2="l_lleg"/>
        <pair geom1="l_dfarm" geom2="r_uleg"/>
        <pair geom1="l_dfarm" geom2="r_lleg"/>
        <pair geom1="r_dfarm" geom2="l_uleg"/>
        <pair geom1="r_dfarm" geom2="l_lleg"/>
        <pair geom1="r_dfarm" geom2="r_uleg"/>
        <pair geom1="r_dfarm" geom2="r_lleg"/>

        <pair geom1="l_uleg" geom2="l_lleg"/>
        <pair geom1="l_uleg" geom2="r_uleg"/>
        <pair geom1="l_uleg" geom2="r_lleg"/>

        <pair geom1="r_uleg" geom2="r_lleg"/>
        <pair geom1="r_uleg" geom2="l_uleg"/>
        <pair geom1="r_uleg" geom2="l_lleg"/>
        
        <pair geom1="r_lleg" geom2="l_lleg"/>

        <pair geom1="l_ankle" geom2="r_lleg"/>
        <pair geom1="r_ankle" geom2="l_lleg"/>
        <pair geom1="l_foot" geom2="r_ankle"/>
        <pair geom1="r_foot" geom2="l_ankle"/>
        <pair geom1="l_foot" geom2="r_lleg"/>
        <pair geom1="r_foot" geom2="l_lleg"/>   

        <!--fingers-->


        <pair geom1="left_f0_0" geom2="l_ankle"/>
        <pair geom1="left_f0_1" geom2="l_ankle"/>
        <pair geom1="left_f0_2" geom2="l_ankle"/>
        <pair geom1="left_f1_0" geom2="l_ankle"/>
        <pair geom1="left_f1_1" geom2="l_ankle"/>
        <pair geom1="left_f1_2" geom2="l_ankle"/>
        <pair geom1="left_f2_0" geom2="l_ankle"/>
        <pair geom1="left_f2_1" geom2="l_ankle"/>
        <pair geom1="left_f2_2" geom2="l_ankle"/>
        <pair geom1="left_f3_0" geom2="l_ankle"/>
        <pair geom1="left_f3_1" geom2="l_ankle"/>
        <pair geom1="left_f3_2" geom2="l_ankle"/>

        <pair geom1="right_f0_0" geom2="r_ankle"/>
        <pair geom1="right_f0_1" geom2="r_ankle"/>
        <pair geom1="right_f0_2" geom2="r_ankle"/>
        <pair geom1="right_f1_0" geom2="r_ankle"/>
        <pair geom1="right_f1_1" geom2="r_ankle"/>
        <pair geom1="right_f1_2" geom2="r_ankle"/>
        <pair geom1="right_f2_0" geom2="r_ankle"/>
        <pair geom1="right_f2_1" geom2="r_ankle"/>
        <pair geom1="right_f2_2" geom2="r_ankle"/>
        <pair geom1="right_f3_0" geom2="r_ankle"/>
        <pair geom1="right_f3_1" geom2="r_ankle"/>
        <pair geom1="right_f3_2" geom2="r_ankle"/>


        <pair geom1="left_f0_0" geom2="l_foot"/>
        <pair geom1="left_f0_1" geom2="l_foot"/>
        <pair geom1="left_f0_2" geom2="l_foot"/>
        <pair geom1="left_f1_0" geom2="l_foot"/>
        <pair geom1="left_f1_1" geom2="l_foot"/>
        <pair geom1="left_f1_2" geom2="l_foot"/>
        <pair geom1="left_f2_0" geom2="l_foot"/>
        <pair geom1="left_f2_1" geom2="l_foot"/>
        <pair geom1="left_f2_2" geom2="l_foot"/>
        <pair geom1="left_f3_0" geom2="l_foot"/>
        <pair geom1="left_f3_1" geom2="l_foot"/>
        <pair geom1="left_f3_2" geom2="l_foot"/>

        <pair geom1="right_f0_0" geom2="r_foot"/>
        <pair geom1="right_f0_1" geom2="r_foot"/>
        <pair geom1="right_f0_2" geom2="r_foot"/>
        <pair geom1="right_f1_0" geom2="r_foot"/>
        <pair geom1="right_f1_1" geom2="r_foot"/>
        <pair geom1="right_f1_2" geom2="r_foot"/>
        <pair geom1="right_f2_0" geom2="r_foot"/>
        <pair geom1="right_f2_1" geom2="r_foot"/>
        <pair geom1="right_f2_2" geom2="r_foot"/>
        <pair geom1="right_f3_0" geom2="r_foot"/>
        <pair geom1="right_f3_1" geom2="r_foot"/>
        <pair geom1="right_f3_2" geom2="r_foot"/>

        <pair geom1="left_f0_0" geom2="l_lleg"/>
        <pair geom1="left_f0_1" geom2="l_lleg"/>
        <pair geom1="left_f0_2" geom2="l_lleg"/>
        <pair geom1="left_f1_0" geom2="l_lleg"/>
        <pair geom1="left_f1_1" geom2="l_lleg"/>
        <pair geom1="left_f1_2" geom2="l_lleg"/>
        <pair geom1="left_f2_0" geom2="l_lleg"/>
        <pair geom1="left_f2_1" geom2="l_lleg"/>
        <pair geom1="left_f2_2" geom2="l_lleg"/>
        <pair geom1="left_f3_0" geom2="l_lleg"/>
        <pair geom1="left_f3_1" geom2="l_lleg"/>
        <pair geom1="left_f3_2" geom2="l_lleg"/>

        <pair geom1="right_f0_0" geom2="r_lleg"/>
        <pair geom1="right_f0_1" geom2="r_lleg"/>
        <pair geom1="right_f0_2" geom2="r_lleg"/>
        <pair geom1="right_f1_0" geom2="r_lleg"/>
        <pair geom1="right_f1_1" geom2="r_lleg"/>
        <pair geom1="right_f1_2" geom2="r_lleg"/>
        <pair geom1="right_f2_0" geom2="r_lleg"/>
        <pair geom1="right_f2_1" geom2="r_lleg"/>
        <pair geom1="right_f2_2" geom2="r_lleg"/>
        <pair geom1="right_f3_0" geom2="r_lleg"/>
        <pair geom1="right_f3_1" geom2="r_lleg"/>
        <pair geom1="right_f3_2" geom2="r_lleg"/>
  

        <pair geom1="right_f0_2" geom2="right_f1_2"/>
        <pair geom1="right_f1_2" geom2="right_f2_2"/>
        <pair geom1="right_f2_2" geom2="right_f3_2"/>

        <pair geom1="left_f0_2" geom2="left_f1_2"/>
        <pair geom1="left_f1_2" geom2="left_f2_2"/>
        <pair geom1="left_f2_2" geom2="left_f3_2"/>

        <pair geom1="right_f0_1" geom2="right_f1_1"/>
        <pair geom1="right_f1_1" geom2="right_f2_1"/>
        <pair geom1="right_f2_1" geom2="right_f3_1"/>

        <pair geom1="left_f0_1" geom2="left_f1_1"/>
        <pair geom1="left_f1_1" geom2="left_f2_1"/>
        <pair geom1="left_f2_1" geom2="left_f3_1"/>

        <pair geom1="right_f0_0" geom2="right_f1_0"/>
        <pair geom1="right_f1_0" geom2="right_f2_0"/>
        <pair geom1="right_f2_0" geom2="right_f3_0"/>

        <pair geom1="left_f0_0" geom2="left_f1_0"/>
        <pair geom1="left_f1_0" geom2="left_f2_0"/>
        <pair geom1="left_f2_0" geom2="left_f3_0"/>

        <pair geom1="r_foot" geom2="right_f0_2"/>
        <pair geom1="l_foot" geom2="right_f0_2"/>
        <pair geom1="r_foot" geom2="right_f1_2"/>
        <pair geom1="l_foot" geom2="right_f1_2"/>
        <pair geom1="r_foot" geom2="right_f2_2"/>
        <pair geom1="l_foot" geom2="right_f2_2"/>
        <pair geom1="r_foot" geom2="right_f3_2"/>
        <pair geom1="l_foot" geom2="right_f3_2"/>
        <pair geom1="r_foot" geom2="left_f0_2"/>
        <pair geom1="l_foot" geom2="left_f0_2"/>
        <pair geom1="r_foot" geom2="left_f1_2"/>
        <pair geom1="l_foot" geom2="left_f1_2"/>
        <pair geom1="r_foot" geom2="left_f2_2"/>
        <pair geom1="l_foot" geom2="left_f2_2"/>
        <pair geom1="r_foot" geom2="left_f3_2"/>
        <pair geom1="l_foot" geom2="left_f3_2"/>
        <pair geom1="r_foot" geom2="right_f0_1"/>
        <pair geom1="l_foot" geom2="right_f0_1"/>
        <pair geom1="r_foot" geom2="right_f1_1"/>
        <pair geom1="l_foot" geom2="right_f1_1"/>
        <pair geom1="r_foot" geom2="right_f2_1"/>
        <pair geom1="l_foot" geom2="right_f2_1"/>
        <pair geom1="r_foot" geom2="right_f3_1"/>
        <pair geom1="l_foot" geom2="right_f3_1"/>
        <pair geom1="r_foot" geom2="right_f0_0"/>
        <pair geom1="l_foot" geom2="right_f0_0"/>
        <pair geom1="r_foot" geom2="right_f1_0"/>
        <pair geom1="l_foot" geom2="right_f1_0"/>
        <pair geom1="r_foot" geom2="right_f2_0"/>
        <pair geom1="l_foot" geom2="right_f2_0"/>
        <pair geom1="r_foot" geom2="right_f3_0"/>
        <pair geom1="l_foot" geom2="left_f0_0"/>
        <pair geom1="r_foot" geom2="left_f0_0"/>
        <pair geom1="l_foot" geom2="left_f1_0"/>
        <pair geom1="r_foot" geom2="left_f1_0"/>
        <pair geom1="l_foot" geom2="left_f2_0"/>
        <pair geom1="r_foot" geom2="left_f2_0"/>
        <pair geom1="l_foot" geom2="left_f3_0"/>
        <pair geom1="r_foot" geom2="left_f3_0"/>


        <pair geom1="r_foot" geom2="l_dfarm"/>
        <pair geom1="l_foot" geom2="l_dfarm"/>

        <pair geom1="r_foot" geom2="r_dfarm"/>
        <pair geom1="l_foot" geom2="r_dfarm"/>






    </contact>
    <asset>
        <mesh name="l_shoulder" file="l_shoulder.stl" />
        <mesh name="l_dfarm" file="l_dfarm.stl" />
        <mesh name="foot" file="foot.stl" />
        <mesh name="l_ufarm" file="l_ufarm.stl" />
        <mesh name="l_lglut" file="l_lglut.stl" />
        <mesh name="l_lleg" file="l_lleg.stl" />
        <mesh name="ankle" file="ankle.stl" />
        <mesh name="l_uarm" file="l_uarm.stl" />
        <mesh name="l_uglut" file="l_uglut.stl" />
        <mesh name="l_uleg" file="l_uleg.stl" />
        <mesh name="ltorso" file="ltorso.stl" />
        <mesh name="mtorso" file="mtorso.stl" />
        <mesh name="pelvis" file="pelvis.stl" />
        <mesh name="utorso" file="utorso.stl" />
        <mesh name="r_dfarm" file="r_dfarm.stl" />
        <mesh name="r_ufarm" file="r_ufarm.stl" />
        <mesh name="r_lglut" file="r_lglut.stl" />
        <mesh name="r_lleg" file="r_lleg.stl" />
        <mesh name="r_shoulder" file="r_shoulder.stl" />
        <mesh name="r_uarm" file="r_uarm.stl" />
        <mesh name="r_uglut" file="r_uglut.stl" />
        <mesh name="r_uleg" file="r_uleg.stl" />
        <mesh name="left_palm" file="left_palm.stl" />
        <mesh name="right_palm" file="right_palm.stl" />
        <mesh name="f0" file="f0.stl" />
        <mesh name="f1" file="f1.stl" />
        <mesh name="f2" file="f2.stl" />

         <texture name="white" type="2d" builtin="checker" rgb1="1 1 1" width="100" height="100" mark="none" markrgb=".8 .8 .8"/>
         <texture name="gray" type="2d" builtin="checker" rgb1="0.25 0.25 0.25" width="100" height="100"/>
         <material name="whitemat" texture="white" texrepeat="0 0" specular="1" shininess=".3" reflectance="0.00001" rgba="1 1 1 1" />
         <material name="graymat" texture="gray" texrepeat="0 0" specular="0" shininess=".3" reflectance="0.00001" />

         <texture type="cube" name="logo" builtin="none"  filefront="textures/whitebackground.png" fileright="textures/whitebackground.png" fileleft="textures/whitebackground.png" fileup="textures/whitebackground.png" filedown="textures/logo.png" fileback="textures/whitebackground.png" />

         <material name="logomat" texture="logo" texrepeat="1 1" specular="0" shininess=".3" reflectance="0.00001" />


    </asset>
    <worldbody>
        <light directional="false" cutoff="60" exponent="1" diffuse="1 1 1" specular=".1 .1 .1" pos="3 3 5" dir="-.3 -.3 -.5"/>
        <geom type="mesh" mesh="pelvis"  material="whitemat"/>
        <body name="    " pos="-0.0125 0 0">
            <inertial pos="-0.0112984 -3.15366e-06 0.0746835" quat="0.997071 0.000128212 0.076485 -0.00012406" mass="2.409" diaginertia="0.003962 0.00341694 0.00169212" />
            <joint name="back_bkz" pos="0 0 0" axis="0 0 1" limited="true" range="-0.663225 0.663225" damping="0.2" />
            <geom type="mesh" mesh="ltorso" />
            <body name="mtorso" pos="0 0 0.16197">
                <inertial pos="-0.00816266 -0.0131245 0.0305974" quat="0.108378 0.49314 0.746335 0.433648" mass="0.69" diaginertia="0.000536243 0.000487378 0.000358057" />
                <joint name="back_bky" pos="0 0 0" axis="0 1 0" limited="true" range="-0.610691 0.438427" damping="0.1" />
                <geom type="mesh" mesh="mtorso" />
                <body name="utorso" pos="0 0 -0.03">
                    <camera name="head_camera" mode="trackcom" pos="0 0 1.68" xyaxes="1 0 0 0 0 1"/>
                    <camera name="lidar" euler="1.55 -1.55 3.14" pos="0 0 1.6" fovy="25"/>
                    <inertial pos="0 -0.048 0.084" quat="0.684588 0.177029 -0.177029 0.684588" mass="3.45" diaginertia="0.011217 0.011 0.00178301" />
                    <joint name="back_bkx" pos="0 0 0" axis="1 0 0" limited="true" range="-0.698132 0.698132" damping="0.1" />
                    <geom type="mesh" mesh="utorso" material="logomat"/>
                    <body name="l_shoulder" pos="0.18 0.42 1.24">
                        <inertial pos="0 0.048 0.084" quat="0.684588 -0.177029 0.177029 0.684588" mass="3.45" diaginertia="0.011217 0.011 0.00178301" />
                        <joint name="l_arm_shx" pos="0 0 0" axis="0 0.967724 0.252012" limited="true" range="-1.5708 1.5708" damping="0.1" />
                        <geom pos="0 0.048 0.084" type="mesh" mesh="l_shoulder"  material="graymat" />
                        <body name="l_uarm" pos="0 0.43 0.12">
                            <inertial pos="0 -0.065 0" quat="0.707107 0.707107 0 0" mass="3.388" diaginertia="0.00656 0.00656 0.00358" />
                            <joint name="l_arm_ely" pos="0 0 0" axis="1 0 0" limited="true" range="-1.57 1.57" damping="0.1" />
                            <geom name="l_uarm" type="mesh" mesh="l_uarm" material="whitemat"/>
                            <body name="l_ufarm" pos="0.23 1.1 0.28">
                                <inertial pos="0 0 0" quat="0.5 0.5 0.5 0.5" mass="2.509" diaginertia="0.00446 0.00446 0.00265" />
                                <joint name="l_arm_elx" pos="0 0 0" axis="0 0 1" limited="true" range="-1.57 0" damping="0.2" />
                                <geom name="l_ufarm" quat="0.648291 0.255185 0.667505 -0.262748" type="mesh" mesh="l_ufarm" material="whitemat" />
                                <body name="l_dfarm" pos="0.17 0.17 -0.01">
                                    <inertial pos="0 -0.065 0" quat="0.707107 0.707107 0 0" mass="3.388" diaginertia="0.00656 0.00656 0.00358" />
                                    <joint name="l_arm_wry" pos="0 0 0" axis="0.707107 0.707107 0" limited="true" range="0 3.14159" damping="0.1" />
                                    <geom quat="0.939373 0 0 -0.342898" type="mesh" mesh="l_dfarm" material="whitemat" name="l_dfarm" />
                                    <geom name="left_palm"pos="0.35 0.35 0" quat="0.620792 0.620297 0.33887 0.33914" type="mesh" mesh="left_palm" />
                                    <body name="left_f0_0" pos="0.425642 0.467806 0" quat="0.664501 0.562692 0.427761 0.242562">
                                        <inertial pos="0 0 0" quat="0.5 0.5 0.5 0.5" mass="0.106" diaginertia="0.00011505 0.00011505 1.1925e-05" />
                                        <joint name="left_f0_j0" pos="0 0 0" axis="0 0 1" limited="true" range="-1.5708 1.5708" damping="1" />
                                        <geom name="left_f0_0" type="mesh" mesh="f0" />
                                        <body name="left_f0_1" pos="0.028 0 0" quat="0.707107 0.707107 0 0">
                                            <inertial pos="0.00697674 0 0" quat="0.5 0.5 0.5 0.5" mass="0.043" diaginertia="2.10767e-05 2.10767e-05 2.65e-06" />
                                                <joint name="left_f0_j1" pos="0 0 0" axis="0 0 1" limited="true" range="-1.5708 1.5708" damping="1" />
                                            <geom name="left_f0_1" type="mesh" mesh="f1" />
                                            <body name="left_f0_2" pos="0.05 0 0">
                                                <inertial pos="0.00930233 0 0" quat="0.5 0.5 0.5 0.5" mass="0.043" diaginertia="2.28821e-05 2.28821e-05 2.3365e-06" />
                                                <joint name="left_f0_j2" pos="0 0 0" axis="0 0 1" limited="true" range="-1.5708 1.5708" damping="1" />
                                                <geom name="left_f0_2" type="mesh" mesh="f2" />
                                            </body>
                                        </body>
                                    </body>
                                    <body name="left_f1_0" pos="0.412156 0.446756 -0.03122" quat="0.664501 0.562692 0.427761 0.242562">
                                        <inertial pos="0 0 0" quat="0.5 0.5 0.5 0.5" mass="0.106" diaginertia="0.00011505 0.00011505 1.1925e-05" />
                                        <joint name="left_f1_j0" pos="0 0 0" axis="0 0 1" limited="true" range="-1.5708 1.5708" damping="1" />
                                        <geom name="left_f1_0" type="mesh" mesh="f0" />
                                        <body name="left_f1_1" pos="0.028 0 0" quat="0.707107 0.707107 0 0">
                                                <inertial pos="0.00697674 0 0" quat="0.5 0.5 0.5 0.5" mass="0.043" diaginertia="2.10767e-05 2.10767e-05 2.65e-06" />
                                            <joint name="left_f1_j1" pos="0 0 0" axis="0 0 1" limited="true" range="-1.5708 1.5708" damping="1" />
                                            <geom name="left_f1_1" type="mesh" mesh="f1" />
                                            <body name="left_f1_2" pos="0.05 0 0">
                                                        <inertial pos="0.00930233 0 0" quat="0.5 0.5 0.5 0.5" mass="0.043" diaginertia="2.28821e-05 2.28821e-05 2.3365e-06" />
                                                <joint name="left_f1_j2" pos="0 0 0" axis="0 0 1" limited="true" range="-1.5708 1.5708" damping="1" />
                                                <geom name="left_f1_2" type="mesh" mesh="f2" />
                                            </body>
                                        </body>
                                    </body>
                                    <body name="left_f2_0" pos="0.398669 0.425706 -0.06245" quat="0.664501 0.562692 0.427761 0.242562">
                                        <inertial pos="0 0 0" quat="0.5 0.5 0.5 0.5" mass="0.106" diaginertia="0.00011505 0.00011505 1.1925e-05" />
                                        <joint name="left_f2_j0" pos="0 0 0" axis="0 0 1" limited="true" range="-1.5708 1.5708" damping="1" />
                                        <geom name="left_f2_0" type="mesh" mesh="f0" />
                                        <body name="left_f2_1" pos="0.028 0 0" quat="0.707107 0.707107 0 0">
                                                <inertial pos="0.00697674 0 0" quat="0.5 0.5 0.5 0.5" mass="0.043" diaginertia="2.10767e-05 2.10767e-05 2.65e-06" />
                                            <joint name="left_f2_j1" pos="0 0 0" axis="0 0 1" limited="true" range="-1.5708 1.5708" damping="1" />
                                            <geom name="left_f2_1" type="mesh" mesh="f1" />
                                            <body name="left_f2_2" pos="0.05 0 0">
                                                        <inertial pos="0.00930233 0 0" quat="0.5 0.5 0.5 0.5" mass="0.043" diaginertia="2.28821e-05 2.28821e-05 2.3365e-06" />
                                                <joint name="left_f2_j2" pos="0 0 0" axis="0 0 1" limited="true" range="-1.5708 1.5708" damping="1" />
                                                <geom name="left_f2_2" type="mesh" mesh="f2" />
                                            </body>
                                        </body>
                                    </body>
                                    <body name="left_f3_0" pos="0.383336 0.376071 0.0438411" quat="0.886464 -0.36731 0.107388 -0.260255">
                                        <inertial pos="0 0 0" quat="0.5 0.5 0.5 0.5" mass="0.106" diaginertia="0.00011505 0.00011505 1.1925e-05" />
                                        <joint name="left_f3_j0" pos="0 0 0" axis="0 0 1" limited="true" range="-1.5708 1.5708" damping="1" />
                                        <geom name="left_f3_0" type="mesh" mesh="f0" />
                                        <body name="left_f3_1" pos="0.028 0 0" quat="0.707107 0.707107 0 0">
                                                <inertial pos="0.00697674 0 0" quat="0.5 0.5 0.5 0.5" mass="0.043" diaginertia="2.10767e-05 2.10767e-05 2.65e-06" />
                                            <joint name="left_f3_j1" pos="0 0 0" axis="0 0 1" limited="true" range="-1.5708 1.5708" damping="1" />
                                            <geom name="left_f3_1" type="mesh" mesh="f1" />
                                            <body name="left_f3_2" pos="0.05 0 0">
                                                        <inertial pos="0.00930233 0 0" quat="0.5 0.5 0.5 0.5" mass="0.043" diaginertia="2.28821e-05 2.28821e-05 2.3365e-06" />
                                                <joint name="left_f3_j2" pos="0 0 0" axis="0 0 1" limited="true" range="-1.5708 1.5708" damping="1" />
                                                <geom name="left_f3_2" type="mesh" mesh="f2" />
                                            </body>
                                        </body>
                                    </body>
                                </body>
                            </body>
                        </body>
                    </body>
                    <body name="r_shoulder" pos="0.18 -0.42 1.24">
                        <inertial pos="0 0 0" quat="0.5 0.5 0.5 0.5" mass="3.012" diaginertia="0.00583 0.00583 0.00319" />
                        <joint name="r_arm_shx" pos="0 0 0" axis="0 -0.967724 0.252012" limited="true" range="-1.5708 1.5708" damping="0.1" />
                        <geom type="mesh" mesh="r_shoulder" material="graymat"/>
                        <body name="r_uarm" pos="0 -0.43 0.18">
                            <inertial pos="0 0.065 0" quat="0.707107 0.707107 0 0" mass="3.388" diaginertia="0.00656 0.00656 0.00358" />
                            <joint name="r_arm_ely" pos="0 0 0" axis="1 0 0" limited="true" range="-1.57 1.57" damping="0.1" />
                            <geom name="r_uarm" type="mesh" mesh="r_uarm" material="whitemat"/>
                            <body name="r_ufarm" pos="0.2 -1.09 0.24">
                                <inertial pos="0 0 0" quat="0.5 0.5 0.5 0.5" mass="2.509" diaginertia="0.00446 0.00446 0.00265" />
                                <joint name="r_arm_elx" pos="0 0 0" axis="0 0 1" limited="true" range="0 1.57" damping="0.2" />
                                <geom name="r_ufarm" quat="0.648291 -0.255185 0.667505 0.262748" type="mesh" mesh="r_ufarm" material="whitemat"/>
                                <body name="r_dfarm" pos="0.17 -0.17 -0.01">
                                    <inertial pos="0 0.065 0" quat="0.707107 0.707107 0 0" mass="3.388" diaginertia="0.00656 0.00656 0.00358" />
                                    <joint name="r_arm_wry" pos="0 0 0" axis="0.707107 -0.707107 0" limited="true" range="0 3.14159" damping="0.1" />
                                    <geom name="r_dfarm" quat="0.939373 0 0 0.342898" type="mesh" mesh="r_dfarm" material="whitemat" />
                                    <geom name="right_palm" pos="0.35 -0.35 0" quat="0.620792 -0.620297 0.33887 -0.33914" type="mesh" mesh="right_palm" />
                                    <body name="right_f0_0" pos="0.425642 -0.467806 0" quat="0.664501 -0.562692 0.427761 -0.242562">
                                        <inertial pos="0 0 0" quat="0.5 0.5 0.5 0.5" mass="0.106" diaginertia="0.00011505 0.00011505 1.1925e-05" />
                                        <joint name="right_f0_j0" pos="0 0 0" axis="0 0 -1" range="-1.5708 1.5708" damping="1" type="hinge" user="9000" />
                                        <geom name="right_f0_0" type="mesh" mesh="f0" />
                                        <body name="right_f0_1" pos="0.028 0 0" quat="0.707107 0.707107 0 0">
                                                <inertial pos="0.00697674 0 0" quat="0.5 0.5 0.5 0.5" mass="0.043" diaginertia="2.10767e-05 2.10767e-05 2.65e-06" />
                                            <joint name="right_f0_j1" pos="0 0 0" axis="0 0 1" limited="true" range="-1.5708 1.5708" damping="1"  />
                                            <geom name="right_f0_1" type="mesh" mesh="f1" />
                                            <body name="right_f0_2" pos="0.05 0 0">
                                                        <inertial pos="0.00930233 0 0" quat="0.5 0.5 0.5 0.5" mass="0.043" diaginertia="2.28821e-05 2.28821e-05 2.3365e-06" />
                                                <joint name="right_f0_j2" pos="0 0 0" axis="0 0 1" limited="true" range="-1.5708 1.5708" damping="1" />
                                                <geom name="right_f0_2" type="mesh" mesh="f2" />
                                            </body>
                                        </body>
                                    </body>
                                    <body name="right_f1_0" pos="0.412156 -0.446756 -0.03122" quat="0.664501 -0.562692 0.427761 -0.242562">
                                        <inertial pos="0 0 0" quat="0.5 0.5 0.5 0.5" mass="0.106" diaginertia="0.00011505 0.00011505 1.1925e-05" />
                                        <joint name="right_f1_j0" pos="0 0 0" axis="0 0 -1" limited="true" range="-1.5708 1.5708"  damping="1"/>
                                        <geom name="right_f1_0" type="mesh" mesh="f0" />
                                        <body name="right_f1_1" pos="0.028 0 0" quat="0.707107 0.707107 0 0">
                                                <inertial pos="0.00697674 0 0" quat="0.5 0.5 0.5 0.5" mass="0.043" diaginertia="2.10767e-05 2.10767e-05 2.65e-06" />
                                            <joint name="right_f1_j1" pos="0 0 0" axis="0 0 1" limited="true" range="-1.5708 1.5708" damping="1" />
                                            <geom name="right_f1_1" type="mesh" mesh="f1" />
                                            <body name="right_f1_2" pos="0.05 0 0">
                                                        <inertial pos="0.00930233 0 0" quat="0.5 0.5 0.5 0.5" mass="0.043" diaginertia="2.28821e-05 2.28821e-05 2.3365e-06" />
                                                <joint name="right_f1_j2" pos="0 0 0" axis="0 0 1" limited="true" range="-1.5708 1.5708" damping="1" />
                                                <geom name="right_f1_2" type="mesh" mesh="f2" />
                                            </body>
                                        </body>
                                    </body>
                                    <body name="right_f2_0" pos="0.398669 -0.425706 -0.06245" quat="0.664501 -0.562692 0.427761 -0.242562">
                                        <inertial pos="0 0 0" quat="0.5 0.5 0.5 0.5" mass="0.106" diaginertia="0.00011505 0.00011505 1.1925e-05" />
                                        <joint name="right_f2_j0" pos="0 0 0" axis="0 0 -1" limited="true" range="-1.5708 1.5708" damping="1" />
                                        <geom name="right_f2_0" type="mesh" mesh="f0" />
                                        <body name="right_f2_1" pos="0.028 0 0" quat="0.707107 0.707107 0 0">
                                                <inertial pos="0.00697674 0 0" quat="0.5 0.5 0.5 0.5" mass="0.043" diaginertia="2.10767e-05 2.10767e-05 2.65e-06" />
                                            <joint name="right_f2_j1" pos="0 0 0" axis="0 0 1" limited="true" range="-1.5708 1.5708" damping="1" />
                                            <geom name="right_f2_1" type="mesh" mesh="f1" />
                                            <body name="right_f2_2" pos="0.05 0 0">
                                                        <inertial pos="0.00930233 0 0" quat="0.5 0.5 0.5 0.5" mass="0.043" diaginertia="2.28821e-05 2.28821e-05 2.3365e-06" />
                                                <joint name="right_f2_j2" pos="0 0 0" axis="0 0 1" limited="true" range="-1.5708 1.5708" damping="1" />
                                                <geom name="right_f2_2" type="mesh" mesh="f2" />
                                            </body>
                                        </body>
                                    </body>
                                    <body name="right_f3_0" pos="0.383336 -0.376071 0.0438411" quat="0.886464 0.36731 0.107388 0.260255">
                                        <inertial pos="0 0 0" quat="0.5 0.5 0.5 0.5" mass="0.106" diaginertia="0.00011505 0.00011505 1.1925e-05" />
                                        <joint name="right_f3_j0" pos="0 0 0" axis="0 0 -1" limited="true" range="-1.5708 1.5708" damping="1" />
                                        <geom name="right_f3_0" type="mesh" mesh="f0" />
                                        <body name="right_f3_1" pos="0.028 0 0" quat="0.707107 0.707107 0 0">
                                                <inertial pos="0.00697674 0 0" quat="0.5 0.5 0.5 0.5" mass="0.043" diaginertia="2.10767e-05 2.10767e-05 2.65e-06" />
                                            <joint name="right_f3_j1" pos="0 0 0" axis="0 0 1" limited="true" range="-1.5708 1.5708" damping="1" />
                                            <geom name="right_f3_1" type="mesh" mesh="f1" />
                                            <body name="right_f3_2" pos="0.05 0 0">
                                                        <inertial pos="0.00930233 0 0" quat="0.5 0.5 0.5 0.5" mass="0.043" diaginertia="2.28821e-05 2.28821e-05 2.3365e-06" />
                                                <joint name="right_f3_j2" pos="0 0 0" axis="0 0 1" limited="true" range="-1.5708 1.5708" damping="1" />
                                                <geom name="right_f3_2" type="mesh" mesh="f2" />
                                            </body>
                                        </body>
                                    </body>
                                </body>
                            </body>
                        </body>
                    </body>
                </body>
            </body>
        </body>
        <body name="l_uglut" pos="0 0.2 -0.32">
            <inertial pos="0.00529262 -0.00344732 0.00313046" quat="0.999122 -7.72169e-05 0.0419028 -0.000305187" mass="0.648" diaginertia="0.000745109 0.000688179 0.000410071" />
            <joint name="l_leg_hpz" pos="0 0 0" axis="0 0 1" limited="true" range="-0.174533 1.22173" damping="0.1" />
            <geom type="mesh" mesh="l_uglut" material="whitemat" />
            <body name="l_lglut" pos="0 0.17 0">
                <inertial pos="0.0133341 0.0170484 -0.0312052" quat="0.353465 0.600383 0.388609 0.602981" mass="0.866" diaginertia="0.00133867 0.000995812 0.000690275" />
                <joint name="l_leg_hpx" pos="0 0 0" axis="1 0 0" limited="true" range="-0.523599 0.523599" damping="0.1" />
                <geom type="mesh" mesh="l_lglut" material="whitemat"/>
               <body name="l_uleg" pos="0 0.1 0">
                    <inertial pos="0 0 -0.21" mass="8.204" diaginertia="0.09 0.09 0.02" />
                    <joint name="l_leg_hpy" pos="0 0 0" axis="0 1 0" limited="true" range="-1.72072 0.524821" damping="0.2" />
                    <geom name="l_uleg" type="mesh" mesh="l_uleg" material="whitemat" />
                    <body name="l_lleg" pos="0.17 0.19 -1.12">
                        <inertial pos="0.001 0 -0.187" quat="0.999751 0 0.0223266 0" mass="5.479" diaginertia="0.0771341 0.076 0.00986594" />
                        <joint name="l_leg_kny" pos="0 0 0" axis="0 1 0" limited="true" range="0 2.38569" damping="0.2" />
                        <geom name="l_lleg" type="mesh" mesh="l_lleg" material="whitemat"/>
                        <body name="l_ankle" pos="-0.15 0 -1.12">
                            <inertial pos="0 0 0" quat="0.5 0.5 -0.5 0.5" mass="0.125" diaginertia="1.30101e-05 1.01674e-05 8.42775e-06" />
                            <joint name="l_leg_aky" pos="0 0 0" axis="1 0 0" limited="true" range="-1 0.7" damping="0.1" />
                            <geom name="l_ankle" type="mesh" mesh="ankle" material="whitemat"/>
                            <body name="l_foot" pos="0 0 -0.19">
                                <inertial pos="0.027 0 -0.067" quat="0 0.707107 0 0.707107" mass="2.05" diaginertia="0.008 0.007 0.002" />
                                <joint name="l_leg_akx" pos="0 0 0" axis="0 1 0" limited="true" range="-0.8 0.8" damping="0.1" />
                                <geom name="l_foot" type="mesh" mesh="foot" material="whitemat"/>
                            </body>
                        </body>
                    </body>
                </body>
            </body>
        </body>
        <body name="r_uglut" pos="0 -0.2 -0.32">
            <inertial pos="0.00529262 0.00344732 0.00313046" quat="0.999122 7.72169e-05 0.0419028 0.000305187" mass="0.648" diaginertia="0.000745109 0.000688179 0.000410071" />
            <joint name="r_leg_hpz" pos="0 0 0" axis="0 0 1" limited="true" range="-1.22173 0.174533" damping="0.1" />
            <geom type="mesh" mesh="r_uglut" material="whitemat" />
            <body name="r_lglut" pos="0 -0.17 0">
                <inertial pos="0.0133341 -0.0170484 -0.0312052" quat="0.602981 0.388609 0.600383 0.353465" mass="0.866" diaginertia="0.00133867 0.000995812 0.000690275" />
                <joint name="r_leg_hpx" pos="0 0 0" axis="1 0 0" limited="true" range="-0.523599 0.523599" damping="0.1" />
                <geom pos="0.01 0 0" type="mesh" mesh="r_lglut" material="whitemat" />
                 <body name="r_uleg" pos="0 -0.1 0">
                    <inertial pos="0 0 -0.21" mass="8.204" diaginertia="0.09 0.09 0.02" />
                    <joint name="r_leg_hpy" pos="0 0 0" axis="0 1 0" limited="true" range="-1.72072 0.524821" damping="0.2" />
                    <geom name="r_uleg" type="mesh" mesh="r_uleg" material="whitemat" />
                    <body name="r_lleg" pos="0.15 -0.19 -1.12">
                        <inertial pos="0.001 0 -0.187" quat="0.999751 0 0.0223266 0" mass="5.479" diaginertia="0.0771341 0.076 0.00986594" />
                        <joint name="r_leg_kny" pos="0 0 0" axis="0 1 0" limited="true" range="0 2.38569" damping="0.2" />
                        <geom name="r_lleg" type="mesh" mesh="r_lleg" material="whitemat" />
                        <body name="r_ankle" pos="-0.15 0 -1.15">
                            <inertial pos="0 0 0" quat="0.5 0.5 -0.5 0.5" mass="0.125" diaginertia="1.30101e-05 1.01674e-05 8.42775e-06" />
                            <joint name="r_leg_aky" pos="0 0 0" axis="1 0 0" limited="true" range="-1 0.7" damping="0.1" />
                            <geom name="r_ankle" type="mesh" mesh="ankle" material="whitemat" />
                            <body name="r_foot" pos="0 0 -0.17">
                                <inertial pos="0.027 0 -0.067" quat="0 0.707107 0 0.707107" mass="2.05" diaginertia="0.008 0.007 0.002" />
                                <joint name="r_leg_akx" pos="0 0 0" axis="0 1 0" limited="true" range="-0.8 0.8" damping="0.1" />
                                <geom name="r_foot" type="mesh" mesh="foot" material="whitemat" />
                            </body>
                        </body>
                    </body>
                </body>
            </body>
        </body>
    </worldbody>


    <actuator>
        <motor name="back_bkz_motor" joint="back_bkz" gear="106"/>
        <motor name="back_bky_motor" joint="back_bky" gear="445" />
        <motor name="back_bkx_motor" joint="back_bkx" gear="300"/>
        <motor name="l_arm_shx_motor" joint="l_arm_shx" gear="99"/>
        <motor name="l_arm_ely_motor" joint="l_arm_ely" gear="63"/>
        <motor name="l_arm_elx_motor" joint="l_arm_elx" gear="112"/>
        <motor name="l_arm_wry_motor" joint="l_arm_wry" gear="25"/>
        <motor name="r_arm_shx_motor" joint="r_arm_shx" gear="99"/>
        <motor name="r_arm_ely_motor" joint="r_arm_ely" gear="63"/>
        <motor name="r_arm_elx_motor" joint="r_arm_elx" gear="112"/>
        <motor name="r_arm_wry_motor" joint="r_arm_wry" gear="25"/>
        <motor name="l_leg_hpz_motor" joint="l_leg_hpz" gear="275"/>
        <motor name="l_leg_hpx_motor" joint="l_leg_hpx" gear="530"/>
        <motor name="l_leg_hpy_motor" joint="l_leg_hpy" gear="840"/>
        <motor name="l_leg_kny_motor" joint="l_leg_kny" gear="890"/>
        <motor name="l_leg_aky_motor" joint="l_leg_aky" gear="740"/>
        <motor name="l_leg_akx_motor" joint="l_leg_akx" gear="360"/>
        <motor name="r_leg_hpz_motor" joint="r_leg_hpz" gear="275"/>
        <motor name="r_leg_hpx_motor" joint="r_leg_hpx" gear="530"/>
        <motor name="r_leg_hpy_motor" joint="r_leg_hpy" gear="840"/>
        <motor name="r_leg_kny_motor" joint="r_leg_kny" gear="890"/>
        <motor name="r_leg_aky_motor" joint="r_leg_aky" gear="740"/>
        <motor name="r_leg_akx_motor" joint="r_leg_akx" gear="360"/> 

        <position name="left_f0_j0_position" joint="left_f0_j0" />
        <position name="left_f0_j1_position" joint="left_f0_j1" />
        <position name="left_f0_j2_position" joint="left_f0_j2" />
        <position name="left_f1_j1_position" joint="left_f1_j1" />
        <position name="left_f1_j0_position" joint="left_f1_j0" />
        <position name="left_f1_j2_position" joint="left_f1_j2" />
        <position name="left_f2_j0_position" joint="left_f2_j0" />
        <position name="left_f2_j1_position" joint="left_f2_j1" />
        <position name="left_f2_j2_position" joint="left_f2_j2" />
        <position name="left_f3_j0_position" joint="left_f3_j0" />
        <position name="left_f3_j1_position" joint="left_f3_j1" />
        <position name="left_f3_j2_position" joint="left_f3_j2" />

        <position name="right_f0_j0_position" joint="right_f0_j0" />
        <position name="right_f0_j1_position" joint="right_f0_j1" />
        <position name="right_f0_j2_position" joint="right_f0_j2" />
        <position name="right_f1_j1_position" joint="right_f1_j1" />
        <position name="right_f1_j0_position" joint="right_f1_j0" />
        <position name="right_f1_j2_position" joint="right_f1_j2" />
        <position name="right_f2_j0_position" joint="right_f2_j0" />
        <position name="right_f2_j1_position" joint="right_f2_j1" />
        <position name="right_f2_j2_position" joint="right_f2_j2" />
        <position name="right_f3_j0_position" joint="right_f3_j0" />
        <position name="right_f3_j1_position" joint="right_f3_j1" />
        <position name="right_f3_j2_position" joint="right_f3_j2" />


 
    </actuator>
</mujoco>
