<?xml version="1.0" encoding="utf-8"?>
<!-- =================================================================================== -->
<!-- |    This document was autogenerated by xacro from atlas_nv_sandia.urdf.xacro     | -->
<!-- |    EDITING THIS FILE BY HAND IS NOT RECOMMENDED                                 | -->
<!-- =================================================================================== -->
<robot name="atlas_skeleton">
  <link name="l_shoulder">
    <inertial>
      <mass value="3.45"/>
      <origin rpy="0 -0 0" xyz="0 0.048 0.084"/>
      <inertia ixx="0.011" ixy="0" ixz="0" iyy="0.009" iyz="-0.004" izz="0.004"/>
    </inertial>
    <visual>
      <origin rpy="0 -0 0" xyz="0 0 0"/>
      <geometry>
        <mesh filename="package://atlas_description/meshes_nv/l_shoulder.dae" scale="1 1 1"/>
      </geometry>
    </visual>
    <collision>
      <origin rpy="0 -0 0" xyz="0 0.048 0.084"/>
      <geometry>
        <mesh filename="package://atlas_description/meshes_nv/l_shoulder.stl" scale="1 1 1"/>
      </geometry>
    </collision>
  </link>
  <link name="l_dfarm">
    <inertial>
      <mass value="3.388"/>
      <origin rpy="0 -0 0" xyz="0 -0.065 0"/>
      <inertia ixx="0.00656" ixy="0" ixz="0" iyy="0.00358" iyz="0" izz="0.00656"/>
    </inertial>
    <visual>
      <origin rpy="-0.0 -0.0 -0.7" xyz="0.0 -0.00 -0.00"/>
      <geometry>
        <mesh filename="package://atlas_description/meshes_nv/l_dfarm.dae" scale="1 1 1"/>
      </geometry>
    </visual>
    <collision>
      <origin rpy="-0.0 -0.0 -0.7" xyz="0.0 -0.00 -0.00"/>
      <geometry>
        <mesh filename="package://atlas_description/meshes_nv/l_dfarm.stl" scale="1 1 1"/>
      </geometry>
    </collision>
  </link>
  <link name="l_foot">
    <inertial>
      <mass value="2.05"/>
      <origin rpy="0 -0 0" xyz="0.027 0 -0.067"/>
      <inertia ixx="0.002" ixy="0" ixz="0" iyy="0.007" iyz="0" izz="0.008"/>
    </inertial>
    <visual>
      <origin rpy="0 -0 0" xyz="0 0 0"/>
      <geometry>
        <mesh filename="package://atlas_description/meshes_nv/l_foot.dae" scale="1 1 1"/>
      </geometry>
    </visual>
    <collision>
      <origin rpy="0 -0 0" xyz="0 0 0"/>
      <geometry>
        <mesh filename="package://atlas_description/meshes_nv/foot.stl" scale="1 1 1"/>
      </geometry>
    </collision>
  </link>
  <link name="l_ufarm">
    <inertial>
      <mass value="2.509"/>
      <origin rpy="0 -0 0" xyz="0 0 0"/>
      <inertia ixx="0.00265" ixy="0" ixz="0" iyy="0.00446" iyz="0" izz="0.00446"/>
    </inertial>
    <visual>
      <origin rpy="0.75 1.6 0.0" xyz="0 0 0"/>
      <geometry>
        <mesh filename="package://atlas_description/meshes_nv/l_ufarm.dae" scale="1 1 1"/>
      </geometry>
    </visual>
    <collision>
      <origin rpy="0.75 1.6 0.0" xyz="0 0 0"/>
      <geometry>
        <mesh filename="package://atlas_description/meshes_nv/l_ufarm.stl" scale="1 1 1"/>
      </geometry>
    </collision>
  </link>
  <link name="l_lglut">
    <inertial>
      <mass value="0.866"/>
      <origin rpy="0 -0 0" xyz="0.0133341 0.0170484 -0.0312052"/>
      <inertia ixx="0.000691326" ixy="-2.24344e-05" ixz="2.50508e-06" iyy="0.00126856" iyz="0.000137862" izz="0.00106487"/>
    </inertial>
    <visual>
      <origin rpy="0 -0 0" xyz="0 0 0"/>
      <geometry>
        <mesh filename="package://atlas_description/meshes_nv/l_lglut.dae" scale="1 1 1"/>
      </geometry>
    </visual>
    <collision>
      <origin rpy="0 -0 0" xyz="0 0 0"/>
      <geometry>
        <mesh filename="package://atlas_description/meshes_nv/l_lglut.stl" scale="1 1 1"/>
      </geometry>
    </collision>
  </link>
  <link name="l_lleg">
    <inertial>
      <mass value="5.479"/>
      <origin rpy="0 -0 0" xyz="0.001 0 -0.187"/>
      <inertia ixx="0.077" ixy="0" ixz="-0.003" iyy="0.076" iyz="0" izz="0.01"/>
    </inertial>
    <visual>
      <origin rpy="0 -0 0" xyz="0 0 0"/>
      <geometry>
        <mesh filename="package://atlas_description/meshes_nv/l_lleg.dae" scale="1 1 1"/>
      </geometry>
    </visual>
    <collision>
      <origin rpy="0 -0 0" xyz="0 0 0"/>
      <geometry>
        <mesh filename="package://atlas_description/meshes_nv/l_lleg.stl" scale="1 1 1"/>
      </geometry>
    </collision>
  </link>
  <link name="l_ankle">
    <inertial>
      <mass value="0.125"/>
      <origin rpy="0 -0 0" xyz="0 0 0"/>
      <inertia ixx="1.01674e-05" ixy="0" ixz="0" iyy="8.42775e-06" iyz="0" izz="1.30101e-05"/>
    </inertial>
    <visual>
      <origin rpy="0 -0 0" xyz="0 0 0"/>
      <geometry>
        <mesh filename="package://atlas_description/meshes_nv/ankle.dae" scale="1 1 1"/>
      </geometry>
    </visual>
    <collision>
      <origin rpy="0 -0 0" xyz="0 0 0"/>
      <geometry>
        <mesh filename="package://atlas_description/meshes_nv/ankle.stl" scale="1 1 1"/>
      </geometry>
    </collision>
  </link>
  <link name="l_uarm">
    <inertial>
      <mass value="3.388"/>
      <origin rpy="0 -0 0" xyz="0 -0.065 0"/>
      <inertia ixx="0.00656" ixy="0" ixz="0" iyy="0.00358" iyz="0" izz="0.00656"/>
    </inertial>
    <visual>
      <origin rpy="0 -0 0" xyz="0 0 0"/>
      <geometry>
        <mesh filename="package://atlas_description/meshes_nv/l_uarm.dae" scale="1 1 1"/>
      </geometry>
    </visual>
    <collision>
      <origin rpy="0 -0 0" xyz="0 0 0"/>
      <geometry>
        <mesh filename="package://atlas_description/meshes_nv/l_uarm.stl" scale="1 1 1"/>
      </geometry>
    </collision>
  </link>
  <link name="l_uglut">
    <inertial>
      <mass value="0.648"/>
      <origin rpy="0 -0 0" xyz="0.00529262 -0.00344732 0.00313046"/>
      <inertia ixx="0.00074276" ixy="-3.79607e-08" ixz="-2.79549e-05" iyy="0.000688179" iyz="-3.2735e-08" izz="0.00041242"/>
    </inertial>
    <visual>
      <origin rpy="0 -0 0" xyz="0 0 0"/>
      <geometry>
        <mesh filename="package://atlas_description/meshes_nv/l_uglut.dae" scale="1 1 1"/>
      </geometry>
    </visual>
    <collision>
      <origin rpy="0 -0 0" xyz="0 0 0"/>
      <geometry>
        <mesh filename="package://atlas_description/meshes_nv/l_uglut.stl" scale="1 1 1"/>
      </geometry>
    </collision>
  </link>
  <link name="l_uleg">
    <inertial>
      <mass value="9.209"/>
      <origin rpy="0 -0 0" xyz="0 0 -0.21"/>
      <inertia ixx="0.09" ixy="0" ixz="0" iyy="0.09" iyz="0" izz="0.02"/>
    </inertial>
    <visual>
      <origin rpy="0 -0 0" xyz="0 0 0"/>
      <geometry>
        <mesh filename="package://atlas_description/meshes_nv/l_uleg.dae" scale="1 1 1"/>
      </geometry>
    </visual>
    <collision>
      <origin rpy="0 -0 0" xyz="0 0 0"/>
      <geometry>
        <mesh filename="package://atlas_description/meshes_nv/l_uleg.stl" scale="1 1 1"/>
      </geometry>
    </collision>
  </link>
  <link name="ltorso">
    <inertial>
      <mass value="2.409"/>
      <origin rpy="0 -0 0" xyz="-0.0112984 -3.15366e-06 0.0746835"/>
      <inertia ixx="0.0039092" ixy="-5.04491e-08" ixz="-0.000342157" iyy="0.00341694" iyz="4.87119e-07" izz="0.00174492"/>
    </inertial>
    <visual>
      <origin rpy="0 -0 0" xyz="0 0 0"/>
      <geometry>
        <mesh filename="package://atlas_description/meshes_nv/ltorso.dae" scale="1 1 1"/>
      </geometry>
    </visual>
    <collision>
      <origin rpy="0 -0 0" xyz="0 0 0"/>
      <geometry>
        <mesh filename="package://atlas_description/meshes_v3/ltorso.stl" scale="1 1 1"/>
      </geometry>
    </collision>
  </link>
  <link name="mtorso">
    <inertial>
      <mass value="0.69"/>
      <origin rpy="0 -0 0" xyz="-0.00816266 -0.0131245 0.0305974"/>
      <inertia ixx="0.000454181" ixy="-6.10764e-05" ixz="3.94009e-05" iyy="0.000483282" iyz="5.27463e-05" izz="0.000444215"/>
    </inertial>
    <visual>
      <origin rpy="0 -0 0" xyz="0 0 0"/>
      <geometry>
        <mesh filename="package://atlas_description/meshes_nv/mtorso.dae" scale="1 1 1"/>
      </geometry>
    </visual>
    <collision>
      <origin rpy="0 -0 0" xyz="0 0 0"/>
      <geometry>
        <mesh filename="package://atlas_description/meshes_nv/mtorso.stl" scale="1 1 1"/>
      </geometry>
    </collision>
  </link>
  <link name="pelvis">
    <inertial>
      <mass value="17.882"/>
      <origin rpy="0 -0 0" xyz="0.0111 0 0.0271"/>
      <inertia ixx="0.1244" ixy="0.0008" ixz="-0.0007" iyy="0.0958" iyz="-0.0005" izz="0.1167"/>
    </inertial>
    <visual>
      <origin rpy="0 -0 0" xyz="0 0 0"/>
      <geometry>
        <mesh filename="package://atlas_description/meshes_nv/pelvis.dae" scale="1 1 1"/>
      </geometry>
    </visual>
    <collision>
      <origin rpy="0 -0 0" xyz="0 0 0"/>
      <geometry>
        <mesh filename="package://atlas_description/meshes_nv/pelvis.stl" scale="1 1 1"/>
      </geometry>
    </collision>
  </link>
  <link name="utorso">
    <inertial>
      <mass value="3.45"/>
      <origin rpy="0 -0 0" xyz="0 -0.048 0.084"/>
      <inertia ixx="0.011" ixy="0" ixz="0" iyy="0.009" iyz="0.004" izz="0.004"/>
    </inertial>
    <visual>
      <origin rpy="0 -0 0" xyz="0 0 0"/>
      <geometry>
        <mesh filename="package://atlas_description/meshes_nv/utorso.dae" scale="1 1 1"/>
      </geometry>
    </visual>
    <collision>
      <origin rpy="0 -0 0" xyz="0 0 0"/>
      <geometry>
        <mesh filename="package://atlas_description/meshes_nv/utorso.stl" scale="1 1 1"/>
      </geometry>
    </collision>
  </link>
  <link name="r_dfarm">
    <inertial>
      <mass value="3.388"/>
      <origin rpy="0 -0 0" xyz="0 0.065 0"/>
      <inertia ixx="0.00656" ixy="0" ixz="0" iyy="0.00358" iyz="0" izz="0.00656"/>
    </inertial>
    <visual>
      <origin rpy="-0.0 -0.0 0.7" xyz="0.0 -0.00 -0.00"/>
      <geometry>
        <mesh filename="package://atlas_description/meshes_nv/r_dfarm.dae" scale="1 1 1"/>
      </geometry>
    </visual>
    <collision>
      <origin rpy="-0.0 -0.0 0.7" xyz="0.00 -0.00 -0.00"/>
      <geometry>
        <mesh filename="package://atlas_description/meshes_nv/r_dfarm.stl" scale="1 1 1"/>
      </geometry>
    </collision>
  </link>
  <link name="r_foot">
    <inertial>
      <mass value="2.05"/>
      <origin rpy="0 -0 0" xyz="0.027 0 -0.067"/>
      <inertia ixx="0.002" ixy="0" ixz="0" iyy="0.007" iyz="0" izz="0.008"/>
    </inertial>
    <visual>
      <origin rpy="0 -0 0" xyz="0 0 0"/>
      <geometry>
        <mesh filename="package://atlas_description/meshes_nv/r_foot.dae" scale="1 1 1"/>
      </geometry>
    </visual>
    <collision>
      <origin rpy="0 -0 0" xyz="0 0 0"/>
      <geometry>
        <mesh filename="package://atlas_description/meshes_nv/foot.stl" scale="1 1 1"/>
      </geometry>
    </collision>
  </link>
  <link name="r_ufarm">
    <inertial>
      <mass value="2.509"/>
      <origin rpy="0 -0 0" xyz="0 0 0"/>
      <inertia ixx="0.00265" ixy="0" ixz="0" iyy="0.00446" iyz="0" izz="0.00446"/>
    </inertial>
    <visual>
      <origin rpy="-0.75 1.5 0.0" xyz="0 0 -0.05"/>
      <geometry>
        <mesh filename="package://atlas_description/meshes_nv/r_ufarm.dae" scale="1 1 1"/>
      </geometry>
    </visual>
    <collision>
      <origin rpy="-0.75 1.6 0.0" xyz="0 0 0"/>
      <geometry>
        <mesh filename="package://atlas_description/meshes_nv/r_ufarm.stl" scale="1 1 1"/>
      </geometry>
    </collision>
  </link>
  <link name="r_lglut">
    <inertial>
      <mass value="0.866"/>
      <origin rpy="0 -0 0" xyz="0.0133341 -0.0170484 -0.0312052"/>
      <inertia ixx="0.000691326" ixy="2.24344e-05" ixz="2.50508e-06" iyy="0.00126856" iyz="-0.000137862" izz="0.00106487"/>
    </inertial>
    <visual>
      <!-- there appears to be a bug in the visuals provided, not aligned with the other left one in x-direction
            <origin xyz="0 0 0" rpy="0 -0 0" />
            -->
      <origin rpy="0 -0 0" xyz="0.01 0 0"/>
      <geometry>
        <mesh filename="package://atlas_description/meshes_nv/r_lglut.dae" scale="1 1 1"/>
      </geometry>
    </visual>
    <collision>
      <origin rpy="0 -0 0" xyz="0.01 0 0"/>
      <geometry>
        <mesh filename="package://atlas_description/meshes_nv/r_lglut.stl" scale="1 1 1"/>
      </geometry>
    </collision>
  </link>
  <link name="r_lleg">
    <inertial>
      <mass value="5.479"/>
      <origin rpy="0 -0 0" xyz="0.001 0 -0.187"/>
      <inertia ixx="0.077" ixy="-0" ixz="-0.003" iyy="0.076" iyz="-0" izz="0.01"/>
    </inertial>
    <visual>
      <origin rpy="0 -0 0" xyz="0 0 0"/>
      <geometry>
        <mesh filename="package://atlas_description/meshes_nv/r_lleg.dae" scale="1 1 1"/>
      </geometry>
    </visual>
    <collision>
      <origin rpy="0 -0 0" xyz="0 0 0"/>
      <geometry>
        <mesh filename="package://atlas_description/meshes_nv/r_lleg.stl" scale="1 1 1"/>
      </geometry>
    </collision>
  </link>
  <link name="r_shoulder">
    <inertial>
      <mass value="3.012"/>
      <origin rpy="0 -0 0" xyz="0 0 0"/>
      <inertia ixx="0.00319" ixy="0" ixz="0" iyy="0.00583" iyz="0" izz="0.00583"/>
    </inertial>
    <visual>
      <origin rpy="0 -0 0" xyz="0 0 0"/>
      <geometry>
        <mesh filename="package://atlas_description/meshes_nv/r_shoulder.dae" scale="1 1 1"/>
      </geometry>
    </visual>
    <collision>
      <origin rpy="0 -0 0" xyz="0 0 0"/>
      <geometry>
        <mesh filename="package://atlas_description/meshes_nv/r_shoulder.stl" scale="1 1 1"/>
      </geometry>
    </collision>
  </link>
  <link name="r_ankle">
    <inertial>
      <mass value="0.125"/>
      <origin rpy="0 -0 0" xyz="0 0 0"/>
      <inertia ixx="1.01674e-05" ixy="0" ixz="0" iyy="8.42775e-06" iyz="0" izz="1.30101e-05"/>
    </inertial>
    <visual>
      <origin rpy="0 -0 0" xyz="0 0 0"/>
      <geometry>
        <mesh filename="package://atlas_description/meshes_nv/ankle.dae" scale="1 1 1"/>
      </geometry>
    </visual>
    <collision>
      <origin rpy="0 -0 0" xyz="0 0 0"/>
      <geometry>
        <mesh filename="package://atlas_description/meshes_nv/ankle.stl" scale="1 1 1"/>
      </geometry>
    </collision>
  </link>
  <link name="r_uarm">
    <inertial>
      <mass value="3.388"/>
      <origin rpy="0 -0 0" xyz="0 0.065 0"/>
      <inertia ixx="0.00656" ixy="0" ixz="0" iyy="0.00358" iyz="0" izz="0.00656"/>
    </inertial>
    <visual>
      <origin rpy="0 -0 0" xyz="0 0 0"/>
      <geometry>
        <mesh filename="package://atlas_description/meshes_nv/r_uarm.dae" scale="1 1 1"/>
      </geometry>
    </visual>
    <collision>
      <origin rpy="0 -0 0" xyz="0 0 0"/>
      <geometry>
        <mesh filename="package://atlas_description/meshes_nv/r_uarm.stl" scale="1 1 1"/>
      </geometry>
    </collision>
  </link>
  <link name="r_uglut">
    <inertial>
      <mass value="0.648"/>
      <origin rpy="0 -0 0" xyz="0.00529262 0.00344732 0.00313046"/>
      <inertia ixx="0.00074276" ixy="3.79607e-08" ixz="-2.79549e-05" iyy="0.000688179" iyz="3.2735e-08" izz="0.00041242"/>
    </inertial>
    <visual>
      <origin rpy="0 -0 0" xyz="0 0 0"/>
      <geometry>
        <mesh filename="package://atlas_description/meshes_nv/r_uglut.dae" scale="1 1 1"/>
      </geometry>
    </visual>
    <collision>
      <origin rpy="0 -0 0" xyz="0 0 0"/>
      <geometry>
        <mesh filename="package://atlas_description/meshes_nv/r_uglut.stl" scale="1 1 1"/>
      </geometry>
    </collision>
  </link>
  <link name="r_uleg">
    <inertial>
      <mass value="9.209"/>
      <origin rpy="0 -0 0" xyz="0 0 -0.21"/>
      <inertia ixx="0.09" ixy="0" ixz="0" iyy="0.09" iyz="0" izz="0.02"/>
    </inertial>
    <visual>
      <origin rpy="0 -0 0" xyz="0 0 0"/>
      <geometry>
        <mesh filename="package://atlas_description/meshes_nv/r_uleg.dae" scale="1 1 1"/>
      </geometry>
    </visual>
    <collision>
      <origin rpy="0 -0 0" xyz="0 0 0"/>
      <geometry>
        <mesh filename="package://atlas_description/meshes_nv/r_uleg.stl" scale="1 1 1"/>
      </geometry>
    </collision>
  </link>
  <joint name="back_bkx" type="revolute">
    <origin rpy="0 -0 0" xyz="0 0 -0.03"/>
    <axis xyz="1 0 0"/>
    <parent link="mtorso"/>
    <child link="utorso"/>
    <dynamics damping="0.1" friction="0"/>
    <limit effort="200" lower="-0.698132" upper="0.698132" velocity="12"/>
    <safety_controller k_position="100" k_velocity="100" soft_lower_limit="-10.6981" soft_upper_limit="10.6981"/>
  </joint>
  <joint name="back_bky" type="revolute">
    <origin rpy="0 -0 0" xyz="0 0 0.16197"/>
    <axis xyz="0 1 0"/>
    <parent link="ltorso"/>
    <child link="mtorso"/>
    <dynamics damping="0.1" friction="0"/>
    <limit effort="206.843" lower="-0.610691" upper="0.438427" velocity="12"/>
    <safety_controller k_position="100" k_velocity="100" soft_lower_limit="-10.6107" soft_upper_limit="10.4384"/>
  </joint>
  <joint name="back_bkz" type="revolute">
    <origin rpy="0 -0 0" xyz="-0.0125 0 0"/>
    <axis xyz="0 0 1"/>
    <parent link="pelvis"/>
    <child link="ltorso"/>
    <dynamics damping="0.2" friction="0"/>
    <limit effort="124.016" lower="-0.663225" upper="0.663225" velocity="12"/>
    <safety_controller k_position="100" k_velocity="100" soft_lower_limit="-10.6632" soft_upper_limit="10.6632"/>
  </joint>
  <joint name="l_arm_elx" type="revolute">
    <origin rpy="0 -0 0" xyz="0.23 1.1 0.28"/>
    <axis xyz="0 0 1"/>
    <parent link="l_uarm"/>
    <child link="l_ufarm"/>
    <dynamics damping="0.2" friction="0"/>
    <limit effort="114" lower="-1.57" upper="0" velocity="12"/>
    <safety_controller k_position="100" k_velocity="100" soft_lower_limit="-10" soft_upper_limit="12.3562"/>
  </joint>
  <joint name="l_arm_ely" type="revolute">
    <origin rpy="0 -0 0" xyz="0 0.43 0.12"/>
    <axis xyz="1 0 0"/>
    <parent link="l_shoulder"/>
    <child link="l_uarm"/>
    <dynamics damping="0.1" friction="0"/>
    <limit effort="114" lower="-1.57" upper="1.57" velocity="12"/>
    <safety_controller k_position="100" k_velocity="100" soft_lower_limit="-10" soft_upper_limit="13.1416"/>
  </joint>
  <joint name="l_arm_shx" type="revolute">
    <origin rpy="0 0.0 0.0" xyz="0.18 0.42 1.24"/>
    <axis xyz="0 0.96 0.25"/>
    <parent link="utorso"/>
    <child link="l_shoulder"/>
    <dynamics damping="0.1" friction="0"/>
    <limit effort="170" lower="-1.5708" upper="1.5708" velocity="12"/>
    <safety_controller k_position="100" k_velocity="100" soft_lower_limit="-11.5708" soft_upper_limit="11.5708"/>
  </joint>
  <joint name="l_arm_wry" type="revolute">
    <!--arm revolute-->
    <origin rpy="0 -0 0" xyz="0.17 0.17 -0.01"/>
    <axis xyz="0.7 0.7 0.0"/>
    <parent link="l_ufarm"/>
    <child link="l_dfarm"/>
    <dynamics damping="0.1" friction="0"/>
    <limit effort="114" lower="0" upper="3.14159" velocity="12"/>
    <safety_controller k_position="100" k_velocity="100" soft_lower_limit="-10" soft_upper_limit="13.1416"/>
  </joint>
  <joint name="l_leg_akx" type="revolute">
    <origin rpy="0 -0 0" xyz="0 0 -0.19"/>
    <axis xyz="0 1 0"/>
    <parent link="l_ankle"/>
    <child link="l_foot"/>
    <dynamics damping="0.1" friction="0"/>
    <limit effort="90" lower="-0.8" upper="0.8" velocity="12"/>
    <safety_controller k_position="100" k_velocity="100" soft_lower_limit="-10.8" soft_upper_limit="10.8"/>
  </joint>
  <joint name="l_leg_aky" type="revolute">
    <origin rpy="0 -0 0" xyz="-0.15 0 -1.15"/>
    <axis xyz="1 0 0"/>
    <parent link="l_lleg"/>
    <child link="l_ankle"/>
    <dynamics damping="0.1" friction="0"/>
    <limit effort="700" lower="-1" upper="0.7" velocity="12"/>
    <safety_controller k_position="100" k_velocity="100" soft_lower_limit="-11" soft_upper_limit="10.7"/>
  </joint>
  <joint name="l_leg_hpx" type="revolute">
    <origin rpy="0 -0 0" xyz="0 0.17 0"/>
    <axis xyz="1 0 0"/>
    <parent link="l_uglut"/>
    <child link="l_lglut"/>
    <dynamics damping="0.1" friction="0"/>
    <limit effort="180" lower="-0.523599" upper="0.523599" velocity="12"/>
    <safety_controller k_position="100" k_velocity="100" soft_lower_limit="-10.5236" soft_upper_limit="10.5236"/>
  </joint>
  <joint name="l_leg_hpy" type="revolute">
    <origin rpy="0 -0 0" xyz="0.0 0.1 0.0"/>
    <axis xyz="0 1 0"/>
    <parent link="l_lglut"/>
    <child link="l_uleg"/>
    <dynamics damping="0.2" friction="0"/>
    <limit effort="260" lower="-1.72072" upper="0.524821" velocity="12"/>
    <safety_controller k_position="100" k_velocity="100" soft_lower_limit="-11.7207" soft_upper_limit="10.5248"/>
  </joint>
  <joint name="l_leg_hpz" type="revolute">
    <origin rpy="0 -0 0" xyz="0 0.2 -0.32"/>
    <axis xyz="0 0 1"/>
    <parent link="pelvis"/>
    <child link="l_uglut"/>
    <dynamics damping="0.1" friction="0"/>
    <limit effort="110" lower="-0.174533" upper="1.22173" velocity="12"/>
    <safety_controller k_position="100" k_velocity="100" soft_lower_limit="-10.1745" soft_upper_limit="11.2217"/>
  </joint>
  <joint name="l_leg_kny" type="revolute">
    <origin rpy="0 -0 0" xyz="0.17 0.19 -1.12"/>
    <axis xyz="0 1 0"/>
    <parent link="l_uleg"/>
    <child link="l_lleg"/>
    <dynamics damping="0.2" friction="0"/>
    <limit effort="220" lower="0" upper="2.38569" velocity="12"/>
    <safety_controller k_position="100" k_velocity="100" soft_lower_limit="-10" soft_upper_limit="12.3857"/>
  </joint>
  <joint name="r_arm_elx" type="revolute">
    <origin rpy="0 -0 0" xyz="0.2 -1.09 0.24"/>
    <axis xyz="0 0 1"/>
    <parent link="r_uarm"/>
    <child link="r_ufarm"/>
    <dynamics damping="0.2" friction="0"/>
    <limit effort="114" lower="0." upper="1.57" velocity="12"/>
    <safety_controller k_position="100" k_velocity="100" soft_lower_limit="-12.3562" soft_upper_limit="10"/>
  </joint>
  <joint name="r_arm_ely" type="revolute">
    <origin rpy="0 -0 0" xyz="0 -0.43 0.18"/>
    <axis xyz="1 0 0"/>
    <parent link="r_shoulder"/>
    <child link="r_uarm"/>
    <dynamics damping="0.1" friction="0"/>
    <limit effort="114" lower="-1.57" upper="1.57" velocity="12"/>
    <safety_controller k_position="100" k_velocity="100" soft_lower_limit="-10" soft_upper_limit="13.1416"/>
  </joint>
  <joint name="r_arm_shx" type="revolute">
    <origin rpy="0 0.0 0.0" xyz="0.18 -0.42 1.24"/>
    <axis xyz="0 -0.96 0.25"/>
    <parent link="utorso"/>
    <child link="r_shoulder"/>
    <dynamics damping="0.1" friction="0"/>
    <limit effort="170" lower="-1.5708" upper="1.5708" velocity="12"/>
    <safety_controller k_position="100" k_velocity="100" soft_lower_limit="-11.5708" soft_upper_limit="11.5708"/>
  </joint>
  <joint name="r_arm_wry" type="revolute">
    <origin rpy="0 -0 0" xyz="0.17 -0.17 -0.01"/>
    <axis xyz="0.7 -0.7 0.0"/>
    <parent link="r_ufarm"/>
    <child link="r_dfarm"/>
    <dynamics damping="0.1" friction="0"/>
    <limit effort="114" lower="0" upper="3.14159" velocity="12"/>
    <safety_controller k_position="100" k_velocity="100" soft_lower_limit="-10" soft_upper_limit="13.1416"/>
  </joint>
  <joint name="r_leg_akx" type="revolute">
    <origin rpy="0 -0 0" xyz="0 0 -0.17"/>
    <axis xyz="0 1 0"/>
    <parent link="r_ankle"/>
    <child link="r_foot"/>
    <dynamics damping="0.1" friction="0"/>
    <limit effort="90" lower="-0.8" upper="0.8" velocity="12"/>
    <safety_controller k_position="100" k_velocity="100" soft_lower_limit="-10.8" soft_upper_limit="10.8"/>
  </joint>
  <joint name="r_leg_aky" type="revolute">
    <origin rpy="0 -0 0" xyz="-0.15 0 -1.15"/>
    <axis xyz="1 0 0"/>
    <parent link="r_lleg"/>
    <child link="r_ankle"/>
    <dynamics damping="0.1" friction="0"/>
    <limit effort="700" lower="-1" upper="0.7" velocity="12"/>
    <safety_controller k_position="100" k_velocity="100" soft_lower_limit="-11" soft_upper_limit="10.7"/>
  </joint>
  <joint name="r_leg_hpx" type="revolute">
    <origin rpy="0 -0 0" xyz="0 -0.17 0"/>
    <axis xyz="1 0 0"/>
    <parent link="r_uglut"/>
    <child link="r_lglut"/>
    <dynamics damping="0.1" friction="0"/>
    <limit effort="180" lower="-0.523599" upper="0.523599" velocity="12"/>
    <safety_controller k_position="100" k_velocity="100" soft_lower_limit="-10.5236" soft_upper_limit="10.5236"/>
  </joint>
  <joint name="r_leg_hpy" type="revolute">
    <origin rpy="0 -0 0" xyz="0.0 -0.1 0.0"/>
    <axis xyz="0 1 0"/>
    <parent link="r_lglut"/>
    <child link="r_uleg"/>
    <dynamics damping="0.2" friction="0"/>
    <limit effort="260" lower="-1.72072" upper="0.524821" velocity="12"/>
    <safety_controller k_position="100" k_velocity="100" soft_lower_limit="-11.7207" soft_upper_limit="10.5248"/>
  </joint>
  <joint name="r_leg_hpz" type="revolute">
    <origin rpy="0 -0 0" xyz="0 -0.2 -0.32"/>
    <axis xyz="0 0 1"/>
    <parent link="pelvis"/>
    <child link="r_uglut"/>
    <dynamics damping="0.1" friction="0"/>
    <limit effort="110" lower="-1.22173" upper="0.174533" velocity="12"/>
    <safety_controller k_position="100" k_velocity="100" soft_lower_limit="-11.2217" soft_upper_limit="10.1745"/>
  </joint>
  <joint name="r_leg_kny" type="revolute">
    <origin rpy="0 -0 0" xyz="0.15 -0.19 -1.12"/>
    <axis xyz="0 1 0"/>
    <parent link="r_uleg"/>
    <child link="r_lleg"/>
    <dynamics damping="0.2" friction="0"/>
    <limit effort="220" lower="0" upper="2.38569" velocity="12"/>
    <safety_controller k_position="100" k_velocity="100" soft_lower_limit="-10" soft_upper_limit="12.3857"/>
  </joint>
  <!--SANDIA HANDS-->
  <link name="left_palm">
    <origin rpy="0 0 0" xyz="0 0 0"/>
    <inertial>
      <mass value="1.303"/>
      <origin xyz="0 0 0"/>
      <!-- solid sphere with 5cm radius -->
      <inertia ixx="0.001303" ixy="0" ixz="0" iyy="0.001303" iyz="0" izz="0.001303"/>
    </inertial>
    <collision>
      <origin rpy="0 0 0" xyz="0 0 0"/>
      <geometry>
        <mesh filename="package://atlas_description/meshes_nv/sandia/palm.stl"/>
      </geometry>
    </collision>
    <visual>
      <origin rpy="0 0 0" xyz="0 0 0"/>
      <geometry>
        <mesh filename="package://atlas_description/meshes_nv/sandia/palm.stl"/>
      </geometry>
      <material name="left_sandia_hand_skin">
        <color rgba="0.835 0.655 0.345 1.0"/>
      </material>
    </visual>
  </link>
  <joint name="left_sandia_hand_joint" type="fixed">
    <parent link="l_dfarm"/>
    <child link="left_palm"/>
    <origin rpy="0 0.0 0.7" xyz="0.35 0.35 0.0"/>
  </joint>
  <link name="left_f0_base">
    <origin rpy="0 0 0" xyz="0 0 0"/>
    <inertial>
      <!-- total mass is 2.303 kg, palm is about 1.303 kg, distribute the rest into _base -->
      <mass value="0.250"/>
      <!-- (2.303 - 1.303) / 4 -->
      <origin xyz="0 0 0"/>
      <!-- model as sphere with radius of 1cm -->
      <inertia ixx="0.00001" ixy="0" ixz="0" iyy="0.00001" iyz="0" izz="0.00001"/>
    </inertial>
  </link>
  <link name="left_f0_fixed_accel">
    <origin rpy="0 0 0" xyz="0 0 0"/>
    <inertial>
      <mass value="0.01"/>
      <origin xyz="0 0 0"/>
      <inertia ixx="0.000001" ixy="0" ixz="0" iyy="0.000001" iyz="0" izz="0.000001"/>
    </inertial>
  </link>
  <link name="left_f0_0">
    <origin rpy="0 0 0" xyz="0 0 0"/>
    <inertial>
      <mass value="0.106"/>
      <!-- F1 -->
      <origin xyz="0 0 0"/>
      <!-- solid cylinder -->
      <inertia ixx="0.000011925" ixy="0" ixz="0" iyy="0.00011505" iyz="0" izz="0.00011505"/>
    </inertial>
    <collision>
      <origin rpy="0 0 0" xyz="0 0 0"/>
      <geometry>
        <mesh filename="package://atlas_description/meshes_nv/sandia/f0.stl"/>
      </geometry>
    </collision>
    <visual>
      <origin rpy="0 0 0" xyz="0 0 0"/>
      <geometry>
        <mesh filename="package://atlas_description/meshes_nv/sandia/f0.stl"/>
      </geometry>
      <material name="left_sandia_hand_skin_suntan">
        <color rgba="0.7 0.4 0.2 1.0"/>
      </material>
    </visual>
  </link>
  <link name="left_f0_1">
    <origin rpy="0 0 0" xyz="0 0 0"/>
    <inertial>
      <mass value="0.033"/>
      <!-- F2 -->
      <origin xyz="0 0 0"/>
      <!-- solid cylinder -->
      <inertia ixx="0.00000165" ixy="0" ixz="0" iyy="0.00001316975" iyz="0" izz="0.00001316975"/>
    </inertial>
    <collision>
      <origin rpy="0 0 0" xyz="0 0 0"/>
      <geometry>
        <mesh filename="package://atlas_description/meshes_nv/sandia/f1.stl"/>
      </geometry>
    </collision>
    <visual>
      <origin rpy="0 0 0" xyz="0 0 0"/>
      <geometry>
        <mesh filename="package://atlas_description/meshes_nv/sandia/f1.stl"/>
      </geometry>
      <material name="left_sandia_hand_skin">
        <color rgba="0.835 0.655 0.345 1.0"/>
      </material>
    </visual>
  </link>
  <link name="left_f0_1_accel">
    <origin rpy="0 0 0" xyz="0 0 0"/>
    <inertial>
      <mass value="0.01"/>
      <origin xyz="0 0 0"/>
      <inertia ixx="0.000001" ixy="0" ixz="0" iyy="0.000001" iyz="0" izz="0.000001"/>
    </inertial>
  </link>
  <link name="left_f0_2">
    <origin rpy="0 0 0" xyz="0 0 0"/>
    <inertial>
      <mass value="0.033"/>
      <!-- F3 -->
      <origin xyz="0 0 0"/>
      <!-- solid cylinder -->
      <inertia ixx="0.0000013365" ixy="0" ixz="0" iyy="0.000009603" iyz="0" izz="0.000009603"/>
    </inertial>
    <collision>
      <origin rpy="0 0 0" xyz="0 0 0"/>
      <geometry>
        <mesh filename="package://atlas_description/meshes_nv/sandia/f2.stl"/>
      </geometry>
    </collision>
    <visual>
      <origin rpy="0 0 0" xyz="0 0 0"/>
      <geometry>
        <mesh filename="package://atlas_description/meshes_nv/sandia/f2.stl"/>
      </geometry>
      <material name="left_sandia_hand_skin_suntan">
        <color rgba="0.8 0.6 0.3 1.0"/>
      </material>
    </visual>
  </link>
  <link name="left_f0_2_accel">
    <origin rpy="0 0 0" xyz="0 0 0"/>
    <inertial>
      <mass value="0.01"/>
      <origin xyz="0 0 0"/>
      <inertia ixx="0.000001" ixy="0" ixz="0" iyy="0.000001" iyz="0" izz="0.000001"/>
    </inertial>
  </link>
  <joint name="left_f0_base" type="fixed">
    <parent link="left_palm"/>
    <child link="left_f0_base"/>
    <origin rpy="0 0 -0.3" xyz="0.14 0.0 0"/>
  </joint>
  <joint name="left_f0_j0" type="revolute">
    <axis xyz="0 0 -1"/>
    <parent link="left_f0_base"/>
    <child link="left_f0_0"/>
    <limit effort="11" lower="-1.57079632679" upper="1.57079632679" velocity="-1"/>
    <safety_controller k_position="1000.0" k_velocity="1000.0" soft_lower_limit="-11.57079" soft_upper_limit="11.57079"/>
    <dynamics damping="1.0"/>
    <origin rpy="0 0 0" xyz="0 0 0"/>
  </joint>
  <joint name="left_f0_j1" type="revolute">
    <axis xyz="0 0 1"/>
    <parent link="left_f0_0"/>
    <child link="left_f0_1"/>
    <limit effort="28" lower="-1.57079632679" upper="1.57079632679" velocity="-1"/>
    <safety_controller k_position="1000.0" k_velocity="1000.0" soft_lower_limit="-11.57079" soft_upper_limit="11.57079"/>
    <dynamics damping="1.0"/>
    <origin rpy="1.57079632679 0 0" xyz="0.028 0 0"/>
  </joint>
  <joint name="left_f0_j2" type="revolute">
    <axis xyz="0 0 1"/>
    <parent link="left_f0_1"/>
    <child link="left_f0_2"/>
    <origin rpy="0 0 0" xyz="0.05 0 0"/>
    <safety_controller k_position="1000.0" k_velocity="1000.0" soft_lower_limit="-11.57079" soft_upper_limit="11.57079"/>
    <dynamics damping="1.0"/>
    <limit effort="28" lower="-1.57079632679" upper="1.57079632679" velocity="-1"/>
  </joint>
  <joint name="left_f0_fixed_accel" type="fixed">
    <parent link="left_f0_base"/>
    <child link="left_f0_fixed_accel"/>
    <origin rpy="0 0 0" xyz="-0.05 0 0"/>
  </joint>
  <joint name="left_f0_1_accel" type="fixed">
    <parent link="left_f0_1"/>
    <child link="left_f0_1_accel"/>
    <origin rpy="-1.57079632679 0 0" xyz="0.03 0 0"/>
  </joint>
  <joint name="left_f0_2_accel" type="fixed">
    <parent link="left_f0_2"/>
    <child link="left_f0_2_accel"/>
    <origin rpy="-1.57079632679 0 0" xyz="0.04 0 0"/>
  </joint>
  
  <link name="left_f1_base">
    <origin rpy="0 0 0" xyz="0 0 0"/>
    <inertial>
      <!-- total mass is 2.303 kg, palm is about 1.303 kg, distribute the rest into _base -->
      <mass value="0.250"/>
      <!-- (2.303 - 1.303) / 4 -->
      <origin xyz="0 0 0"/>
      <!-- model as sphere with radius of 1cm -->
      <inertia ixx="0.00001" ixy="0" ixz="0" iyy="0.00001" iyz="0" izz="0.00001"/>
    </inertial>
  </link>
  <link name="left_f1_fixed_accel">
    <origin rpy="0 0 0" xyz="0 0 0"/>
    <inertial>
      <mass value="0.01"/>
      <origin xyz="0 0 0"/>
      <inertia ixx="0.000001" ixy="0" ixz="0" iyy="0.000001" iyz="0" izz="0.000001"/>
    </inertial>
  </link>
  <link name="left_f1_0">
    <origin rpy="0 0 0" xyz="0 0 0"/>
    <inertial>
      <mass value="0.106"/>
      <!-- F1 -->
      <origin xyz="0 0 0"/>
      <!-- solid cylinder -->
      <inertia ixx="0.000011925" ixy="0" ixz="0" iyy="0.00011505" iyz="0" izz="0.00011505"/>
    </inertial>
    <collision>
      <origin rpy="0 0 0" xyz="0 0 0"/>
      <geometry>
        <mesh filename="package://atlas_description/meshes_nv/sandia/f0.stl"/>
      </geometry>
    </collision>
    <visual>
      <origin rpy="0 0 0" xyz="0 0 0"/>
      <geometry>
        <mesh filename="package://atlas_description/meshes_nv/sandia/f0.stl"/>
      </geometry>
      <material name="left_sandia_hand_skin_suntan">
        <color rgba="0.7 0.4 0.2 1.0"/>
      </material>
    </visual>
  </link>
  <link name="left_f1_1">
    <origin rpy="0 0 0" xyz="0 0 0"/>
    <inertial>
      <mass value="0.033"/>
      <!-- F2 -->
      <origin xyz="0 0 0"/>
      <!-- solid cylinder -->
      <inertia ixx="0.00000165" ixy="0" ixz="0" iyy="0.00001316975" iyz="0" izz="0.00001316975"/>
    </inertial>
    <collision>
      <origin rpy="0 0 0" xyz="0 0 0"/>
      <geometry>
        <mesh filename="package://atlas_description/meshes_nv/sandia/f1.stl"/>
      </geometry>
    </collision>
    <visual>
      <origin rpy="0 0 0" xyz="0 0 0"/>
      <geometry>
        <mesh filename="package://atlas_description/meshes_nv/sandia/f1.stl"/>
      </geometry>
      <material name="left_sandia_hand_skin">
        <color rgba="0.835 0.655 0.345 1.0"/>
      </material>
    </visual>
  </link>
  <link name="left_f1_1_accel">
    <origin rpy="0 0 0" xyz="0 0 0"/>
    <inertial>
      <mass value="0.01"/>
      <origin xyz="0 0 0"/>
      <inertia ixx="0.000001" ixy="0" ixz="0" iyy="0.000001" iyz="0" izz="0.000001"/>
    </inertial>
  </link>
  <link name="left_f1_2">
    <origin rpy="0 0 0" xyz="0 0 0"/>
    <inertial>
      <mass value="0.033"/>
      <!-- F3 -->
      <origin xyz="0 0 0"/>
      <!-- solid cylinder -->
      <inertia ixx="0.0000013365" ixy="0" ixz="0" iyy="0.000009603" iyz="0" izz="0.000009603"/>
    </inertial>
    <collision>
      <origin rpy="0 0 0" xyz="0 0 0"/>
      <geometry>
        <mesh filename="package://atlas_description/meshes_nv/sandia/f2.stl"/>
      </geometry>
    </collision>
    <visual>
      <origin rpy="0 0 0" xyz="0 0 0"/>
      <geometry>
        <mesh filename="package://atlas_description/meshes_nv/sandia/f2.stl"/>
      </geometry>
      <material name="left_sandia_hand_skin_suntan">
        <color rgba="0.8 0.6 0.3 1.0"/>
      </material>
    </visual>
  </link>
  <link name="left_f1_2_accel">
    <origin rpy="0 0 0" xyz="0 0 0"/>
    <inertial>
      <mass value="0.01"/>
      <origin xyz="0 0 0"/>
      <inertia ixx="0.000001" ixy="0" ixz="0" iyy="0.000001" iyz="0" izz="0.000001"/>
    </inertial>
  </link>
  <joint name="left_f1_base" type="fixed">
    <parent link="left_palm"/>
    <child link="left_f1_base"/>
    <origin rpy="0 0 -0.3" xyz="0.115 -0.03122 0"/>
  </joint>
  <joint name="left_f1_j0" type="revolute">
    <axis xyz="0 0 -1"/>
    <parent link="left_f1_base"/>
    <child link="left_f1_0"/>
    <limit effort="11" lower="-1.57079632679" upper="1.57079632679" velocity="-1"/>
    <safety_controller k_position="1000.0" k_velocity="1000.0" soft_lower_limit="-11.57079" soft_upper_limit="11.57079"/>
    <dynamics damping="1.0"/>
    <origin rpy="0 0 0" xyz="0 0 0"/>
  </joint>
  <joint name="left_f1_j1" type="revolute">
    <axis xyz="0 0 1"/>
    <parent link="left_f1_0"/>
    <child link="left_f1_1"/>
    <limit effort="28" lower="-1.57079632679" upper="1.57079632679" velocity="-1"/>
    <safety_controller k_position="1000.0" k_velocity="1000.0" soft_lower_limit="-11.57079" soft_upper_limit="11.57079"/>
    <dynamics damping="1.0"/>
    <origin rpy="1.57079632679 0 0" xyz="0.028 0 0"/>
  </joint>
  <joint name="left_f1_j2" type="revolute">
    <axis xyz="0 0 1"/>
    <parent link="left_f1_1"/>
    <child link="left_f1_2"/>
    <origin rpy="0 0 0" xyz="0.05 0 0"/>
    <safety_controller k_position="1000.0" k_velocity="1000.0" soft_lower_limit="-11.57079" soft_upper_limit="11.57079"/>
    <dynamics damping="1.0"/>
    <limit effort="28" lower="-1.57079632679" upper="1.57079632679" velocity="-1"/>
  </joint>
  <joint name="left_f1_fixed_accel" type="fixed">
    <parent link="left_f1_base"/>
    <child link="left_f1_fixed_accel"/>
    <origin rpy="0 0 0" xyz="-0.05 0 0"/>
  </joint>
  <joint name="left_f1_1_accel" type="fixed">
    <parent link="left_f1_1"/>
    <child link="left_f1_1_accel"/>
    <origin rpy="-1.57079632679 0 0" xyz="0.03 0 0"/>
  </joint>
  <joint name="left_f1_2_accel" type="fixed">
    <parent link="left_f1_2"/>
    <child link="left_f1_2_accel"/>
    <origin rpy="-1.57079632679 0 0" xyz="0.04 0 0"/>
  </joint>
  
  <link name="left_f2_base">
    <origin rpy="0 0 0" xyz="0 0 0"/>
    <inertial>
      <!-- total mass is 2.303 kg, palm is about 1.303 kg, distribute the rest into _base -->
      <mass value="0.250"/>
      <!-- (2.303 - 1.303) / 4 -->
      <origin xyz="0 0 0"/>
      <!-- model as sphere with radius of 1cm -->
      <inertia ixx="0.00001" ixy="0" ixz="0" iyy="0.00001" iyz="0" izz="0.00001"/>
    </inertial>
  </link>
  <link name="left_f2_fixed_accel">
    <origin rpy="0 0 0" xyz="0 0 0"/>
    <inertial>
      <mass value="0.01"/>
      <origin xyz="0 0 0"/>
      <inertia ixx="0.000001" ixy="0" ixz="0" iyy="0.000001" iyz="0" izz="0.000001"/>
    </inertial>
  </link>
  <link name="left_f2_0">
    <origin rpy="0 0 0" xyz="0 0 0"/>
    <inertial>
      <mass value="0.106"/>
      <!-- F1 -->
      <origin xyz="0 0 0"/>
      <!-- solid cylinder -->
      <inertia ixx="0.000011925" ixy="0" ixz="0" iyy="0.00011505" iyz="0" izz="0.00011505"/>
    </inertial>
    <collision>
      <origin rpy="0 0 0" xyz="0 0 0"/>
      <geometry>
        <mesh filename="package://atlas_description/meshes_nv/sandia/f0.stl"/>
      </geometry>
    </collision>
    <visual>
      <origin rpy="0 0 0" xyz="0 0 0"/>
      <geometry>
        <mesh filename="package://atlas_description/meshes_nv/sandia/f0.stl"/>
      </geometry>
      <material name="left_sandia_hand_skin_suntan">
        <color rgba="0.7 0.4 0.2 1.0"/>
      </material>
    </visual>
  </link>
  <link name="left_f2_1">
    <origin rpy="0 0 0" xyz="0 0 0"/>
    <inertial>
      <mass value="0.033"/>
      <!-- F2 -->
      <origin xyz="0 0 0"/>
      <!-- solid cylinder -->
      <inertia ixx="0.00000165" ixy="0" ixz="0" iyy="0.00001316975" iyz="0" izz="0.00001316975"/>
    </inertial>
    <collision>
      <origin rpy="0 0 0" xyz="0 0 0"/>
      <geometry>
        <mesh filename="package://atlas_description/meshes_nv/sandia/f1.stl"/>
      </geometry>
    </collision>
    <visual>
      <origin rpy="0 0 0" xyz="0 0 0"/>
      <geometry>
        <mesh filename="package://atlas_description/meshes_nv/sandia/f1.stl"/>
      </geometry>
      <material name="left_sandia_hand_skin">
        <color rgba="0.835 0.655 0.345 1.0"/>
      </material>
    </visual>
  </link>
  <link name="left_f2_1_accel">
    <origin rpy="0 0 0" xyz="0 0 0"/>
    <inertial>
      <mass value="0.01"/>
      <origin xyz="0 0 0"/>
      <inertia ixx="0.000001" ixy="0" ixz="0" iyy="0.000001" iyz="0" izz="0.000001"/>
    </inertial>
  </link>
  <link name="left_f2_2">
    <origin rpy="0 0 0" xyz="0 0 0"/>
    <inertial>
      <mass value="0.033"/>
      <!-- F3 -->
      <origin xyz="0 0 0"/>
      <!-- solid cylinder -->
      <inertia ixx="0.0000013365" ixy="0" ixz="0" iyy="0.000009603" iyz="0" izz="0.000009603"/>
    </inertial>
    <collision>
      <origin rpy="0 0 0" xyz="0 0 0"/>
      <geometry>
        <mesh filename="package://atlas_description/meshes_nv/sandia/f2.stl"/>
      </geometry>
    </collision>
    <visual>
      <origin rpy="0 0 0" xyz="0 0 0"/>
      <geometry>
        <mesh filename="package://atlas_description/meshes_nv/sandia/f2.stl"/>
      </geometry>
      <material name="left_sandia_hand_skin_suntan">
        <color rgba="0.8 0.6 0.3 1.0"/>
      </material>
    </visual>
  </link>
  <link name="left_f2_2_accel">
    <origin rpy="0 0 0" xyz="0 0 0"/>
    <inertial>
      <mass value="0.01"/>
      <origin xyz="0 0 0"/>
      <inertia ixx="0.000001" ixy="0" ixz="0" iyy="0.000001" iyz="0" izz="0.000001"/>
    </inertial>
  </link>
  <joint name="left_f2_base" type="fixed">
    <parent link="left_palm"/>
    <child link="left_f2_base"/>
    <origin rpy="0 0 -0.3" xyz="0.09 -0.06245 0"/>
  </joint>
  <joint name="left_f2_j0" type="revolute">
    <axis xyz="0 0 -1"/>
    <parent link="left_f2_base"/>
    <child link="left_f2_0"/>
    <limit effort="11" lower="-1.57079632679" upper="1.57079632679" velocity="-1"/>
    <safety_controller k_position="1000.0" k_velocity="1000.0" soft_lower_limit="-11.57079" soft_upper_limit="11.57079"/>
    <dynamics damping="1.0"/>
    <origin rpy="0 0 0" xyz="0 0 0"/>
  </joint>
  <joint name="left_f2_j1" type="revolute">
    <axis xyz="0 0 1"/>
    <parent link="left_f2_0"/>
    <child link="left_f2_1"/>
    <limit effort="28" lower="-1.57079632679" upper="1.57079632679" velocity="-1"/>
    <safety_controller k_position="1000.0" k_velocity="1000.0" soft_lower_limit="-11.57079" soft_upper_limit="11.57079"/>
    <dynamics damping="1.0"/>
    <origin rpy="1.57079632679 0 0" xyz="0.028 0 0"/>
  </joint>
  <joint name="left_f2_j2" type="revolute">
    <axis xyz="0 0 1"/>
    <parent link="left_f2_1"/>
    <child link="left_f2_2"/>
    <origin rpy="0 0 0" xyz="0.05 0 0"/>
    <safety_controller k_position="1000.0" k_velocity="1000.0" soft_lower_limit="-11.57079" soft_upper_limit="11.57079"/>
    <dynamics damping="1.0"/>
    <limit effort="28" lower="-1.57079632679" upper="1.57079632679" velocity="-1"/>
  </joint>
  <joint name="left_f2_fixed_accel" type="fixed">
    <parent link="left_f2_base"/>
    <child link="left_f2_fixed_accel"/>
    <origin rpy="0 0 0" xyz="-0.05 0 0"/>
  </joint>
  <joint name="left_f2_1_accel" type="fixed">
    <parent link="left_f2_1"/>
    <child link="left_f2_1_accel"/>
    <origin rpy="-1.57079632679 0 0" xyz="0.03 0 0"/>
  </joint>
  <joint name="left_f2_2_accel" type="fixed">
    <parent link="left_f2_2"/>
    <child link="left_f2_2_accel"/>
    <origin rpy="-1.57079632679 0 0" xyz="0.04 0 0"/>
  </joint>
 
  <link name="left_f3_base">
    <origin rpy="0 0 0" xyz="0 0 0"/>
    <inertial>
      <!-- total mass is 2.303 kg, palm is about 1.303 kg, distribute the rest into _base -->
      <mass value="0.250"/>
      <!-- (2.303 - 1.303) / 4 -->
      <origin xyz="0 0 0"/>
      <!-- model as sphere with radius of 1cm -->
      <inertia ixx="0.00001" ixy="0" ixz="0" iyy="0.00001" iyz="0" izz="0.00001"/>
    </inertial>
  </link>
  <link name="left_f3_fixed_accel">
    <origin rpy="0 0 0" xyz="0 0 0"/>
    <inertial>
      <mass value="0.01"/>
      <origin xyz="0 0 0"/>
      <inertia ixx="0.000001" ixy="0" ixz="0" iyy="0.000001" iyz="0" izz="0.000001"/>
    </inertial>
  </link>
  <link name="left_f3_0">
    <origin rpy="0 0 0" xyz="0 0 0"/>
    <inertial>
      <mass value="0.106"/>
      <!-- F1 -->
      <origin xyz="0 0 0"/>
      <!-- solid cylinder -->
      <inertia ixx="0.000011925" ixy="0" ixz="0" iyy="0.00011505" iyz="0" izz="0.00011505"/>
    </inertial>
    <collision>
      <origin rpy="0 0 0" xyz="0 0 0"/>
      <geometry>
        <mesh filename="package://atlas_description/meshes_nv/sandia/f0.stl"/>
      </geometry>
    </collision>
    <visual>
      <origin rpy="0 0 0" xyz="0 0 0"/>
      <geometry>
        <mesh filename="package://atlas_description/meshes_nv/sandia/f0.stl"/>
      </geometry>
      <material name="left_sandia_hand_skin_suntan">
        <color rgba="0.7 0.4 0.2 1.0"/>
      </material>
    </visual>
  </link>
  <link name="left_f3_1">
    <origin rpy="0 0 0" xyz="0 0 0"/>
    <inertial>
      <mass value="0.033"/>
      <!-- F2 -->
      <origin xyz="0 0 0"/>
      <!-- solid cylinder -->
      <inertia ixx="0.00000165" ixy="0" ixz="0" iyy="0.00001316975" iyz="0" izz="0.00001316975"/>
    </inertial>
    <collision>
      <origin rpy="0 0 0" xyz="0 0 0"/>
      <geometry>
        <mesh filename="package://atlas_description/meshes_nv/sandia/f1.stl"/>
      </geometry>
    </collision>
    <visual>
      <origin rpy="0 0 0" xyz="0 0 0"/>
      <geometry>
        <mesh filename="package://atlas_description/meshes_nv/sandia/f1.stl"/>
      </geometry>
      <material name="left_sandia_hand_skin">
        <color rgba="0.835 0.655 0.345 1.0"/>
      </material>
    </visual>
  </link>
  <link name="left_f3_1_accel">
    <origin rpy="0 0 0" xyz="0 0 0"/>
    <inertial>
      <mass value="0.01"/>
      <origin xyz="0 0 0"/>
      <inertia ixx="0.000001" ixy="0" ixz="0" iyy="0.000001" iyz="0" izz="0.000001"/>
    </inertial>
  </link>
  <link name="left_f3_2">
    <origin rpy="0 0 0" xyz="0 0 0"/>
    <inertial>
      <mass value="0.033"/>
      <!-- F3 -->
      <origin xyz="0 0 0"/>
      <!-- solid cylinder -->
      <inertia ixx="0.0000013365" ixy="0" ixz="0" iyy="0.000009603" iyz="0" izz="0.000009603"/>
    </inertial>
    <collision>
      <origin rpy="0 0 0" xyz="0 0 0"/>
      <geometry>
        <mesh filename="package://atlas_description/meshes_nv/sandia/f2.stl"/>
      </geometry>
    </collision>
    <visual>
      <origin rpy="0 0 0" xyz="0 0 0"/>
      <geometry>
        <mesh filename="package://atlas_description/meshes_nv/sandia/f2.stl"/>
      </geometry>
      <material name="left_sandia_hand_skin_suntan">
        <color rgba="0.8 0.6 0.3 1.0"/>
      </material>
    </visual>
  </link>
  <link name="left_f3_2_accel">
    <origin rpy="0 0 0" xyz="0 0 0"/>
    <inertial>
      <mass value="0.01"/>
      <origin xyz="0 0 0"/>
      <inertia ixx="0.000001" ixy="0" ixz="0" iyy="0.000001" iyz="0" izz="0.000001"/>
    </inertial>
  </link>
  <joint name="left_f3_base" type="fixed">
    <parent link="left_palm"/>
    <child link="left_f3_base"/>
    <origin rpy="0 -1.57079632679 2.3562" xyz="0.03995 0.04383 0.014"/>
  </joint>
  <joint name="left_f3_j0" type="revolute">
    <axis xyz="0 0 -1"/>
    <parent link="left_f3_base"/>
    <child link="left_f3_0"/>
    <limit effort="11" lower="-1.57079632679" upper="1.57079632679" velocity="-1"/>
    <safety_controller k_position="1000.0" k_velocity="1000.0" soft_lower_limit="-11.57079" soft_upper_limit="11.57079"/>
    <dynamics damping="1.0"/>
    <origin rpy="0 0 0" xyz="0 0 0"/>
  </joint>
  <joint name="left_f3_j1" type="revolute">
    <axis xyz="0 0 1"/>
    <parent link="left_f3_0"/>
    <child link="left_f3_1"/>
    <limit effort="28" lower="-1.57079632679" upper="1.57079632679" velocity="-1"/>
    <safety_controller k_position="1000.0" k_velocity="1000.0" soft_lower_limit="-11.57079" soft_upper_limit="11.57079"/>
    <dynamics damping="1.0"/>
    <origin rpy="1.57079632679 0 0" xyz="0.028 0 0"/>
  </joint>
  <joint name="left_f3_j2" type="revolute">
    <axis xyz="0 0 1"/>
    <parent link="left_f3_1"/>
    <child link="left_f3_2"/>
    <origin rpy="0 0 0" xyz="0.05 0 0"/>
    <safety_controller k_position="1000.0" k_velocity="1000.0" soft_lower_limit="-11.57079" soft_upper_limit="11.57079"/>
    <dynamics damping="1.0"/>
    <limit effort="28" lower="-1.57079632679" upper="1.57079632679" velocity="-1"/>
  </joint>
  <joint name="left_f3_fixed_accel" type="fixed">
    <parent link="left_f3_base"/>
    <child link="left_f3_fixed_accel"/>
    <origin rpy="0 0 0" xyz="-0.05 0 0"/>
  </joint>
  <joint name="left_f3_1_accel" type="fixed">
    <parent link="left_f3_1"/>
    <child link="left_f3_1_accel"/>
    <origin rpy="-1.57079632679 0 0" xyz="0.03 0 0"/>
  </joint>
  <joint name="left_f3_2_accel" type="fixed">
    <parent link="left_f3_2"/>
    <child link="left_f3_2_accel"/>
    <origin rpy="-1.57079632679 0 0" xyz="0.04 0 0"/>
  </joint>
 
  <joint name="left_palm_left_camera_frame_joint" type="fixed">
    <origin rpy="-0.6708 -1.57079632679 3.14159265359" xyz="0.0435128991906 -0.0451672761576 0.025"/>
    <parent link="left_palm"/>
    <child link="left_palm_left_camera_frame"/>
  </joint>
  <link name="left_palm_left_camera_frame">
    <inertial>
      <mass value="0.01"/>
      <origin xyz="0 0 0"/>
      <inertia ixx="0.0001" ixy="0.0" ixz="0.0" iyy="0.0001" iyz="0.0" izz="0.0001"/>
    </inertial>
    <visual group="default">
      <origin rpy="0 0 0" xyz="0 0 0"/>
      <geometry>
        <box size="0.003 0.010 0.007"/>
      </geometry>
    </visual>
  </link>
  <joint name="left_palm_left_camera_optical_frame_joint" type="fixed">
    <origin rpy="-1.57079632679 0.0 -1.57079632679" xyz="0 0 0"/>
    <parent link="left_palm_left_camera_frame"/>
    <child link="left_palm_left_camera_optical_frame"/>
  </joint>
  <link name="left_palm_left_camera_optical_frame"/>
 
  <joint name="left_palm_right_camera_frame_joint" type="fixed">
    <origin rpy="-0.6708 -1.57079632679 3.14159265359" xyz="0.0683774130138 -0.0138342911048 0.025"/>
    <parent link="left_palm"/>
    <child link="left_palm_right_camera_frame"/>
  </joint>
  <link name="left_palm_right_camera_frame">
    <inertial>
      <mass value="0.01"/>
      <origin xyz="0 0 0"/>
      <inertia ixx="0.0001" ixy="0.0" ixz="0.0" iyy="0.0001" iyz="0.0" izz="0.0001"/>
    </inertial>
    <visual group="default">
      <origin rpy="0 0 0" xyz="0 0 0"/>
      <geometry>
        <box size="0.003 0.010 0.007"/>
      </geometry>
    </visual>
  </link>
  <joint name="left_palm_right_camera_optical_frame_joint" type="fixed">
    <origin rpy="-1.57079632679 0.0 -1.57079632679" xyz="0 0 0"/>
    <parent link="left_palm_right_camera_frame"/>
    <child link="left_palm_right_camera_optical_frame"/>
  </joint>
  <link name="left_palm_right_camera_optical_frame"/>
 
  <link name="right_palm">
    <origin rpy="0 0 0" xyz="0 0 0"/>
    <inertial>
      <mass value="1.303"/>
      <origin xyz="0 0 0"/>
      <!-- solid sphere with 5cm radius -->
      <inertia ixx="0.001303" ixy="0" ixz="0" iyy="0.001303" iyz="0" izz="0.001303"/>
    </inertial>
    <collision>
      <origin rpy="0 0 0" xyz="0 0 0"/>
      <geometry>
        <mesh filename="package://atlas_description/meshes_nv/sandia/palm.stl"/>
      </geometry>
    </collision>
    <visual>
      <origin rpy="0 0 0" xyz="0 0 0"/>
      <geometry>
        <mesh filename="package://atlas_description/meshes_nv/sandia/palm.stl"/>
      </geometry>
      <material name="right_sandia_hand_skin">
        <color rgba="0.835 0.655 0.345 1.0"/>
      </material>
    </visual>
  </link>
  <joint name="right_sandia_hand_joint" type="fixed">
    <parent link="r_dfarm"/>
    <child link="right_palm"/>
    <origin rpy="0 0.0 -0.7" xyz="0.35 -0.35 -0.0"/>
  </joint>
  <link name="right_f0_base">
    <origin rpy="0 0 0" xyz="0 0 0"/>
    <inertial>
      <!-- total mass is 2.303 kg, palm is about 1.303 kg, distribute the rest into _base -->
      <mass value="0.250"/>
      <!-- (2.303 - 1.303) / 4 -->
      <origin xyz="0 0 0"/>
      <!-- model as sphere with radius of 1cm -->
      <inertia ixx="0.00001" ixy="0" ixz="0" iyy="0.00001" iyz="0" izz="0.00001"/>
    </inertial>
  </link>
  <link name="right_f0_fixed_accel">
    <origin rpy="0 0 0" xyz="0 0 0"/>
    <inertial>
      <mass value="0.01"/>
      <origin xyz="0 0 0"/>
      <inertia ixx="0.000001" ixy="0" ixz="0" iyy="0.000001" iyz="0" izz="0.000001"/>
    </inertial>
  </link>
  <link name="right_f0_0">
    <origin rpy="0 0 0" xyz="0 0 0"/>
    <inertial>
      <mass value="0.106"/>
      <!-- F1 -->
      <origin xyz="0 0 0"/>
      <!-- solid cylinder -->
      <inertia ixx="0.000011925" ixy="0" ixz="0" iyy="0.00011505" iyz="0" izz="0.00011505"/>
    </inertial>
    <collision>
      <origin rpy="0 0 0" xyz="0 0 0"/>
      <geometry>
        <mesh filename="package://atlas_description/meshes_nv/sandia/f0.stl"/>
      </geometry>
    </collision>
    <visual>
      <origin rpy="0 0 0" xyz="0 0 0"/>
      <geometry>
        <mesh filename="package://atlas_description/meshes_nv/sandia/f0.stl"/>
      </geometry>
      <material name="right_sandia_hand_skin_suntan">
        <color rgba="0.7 0.4 0.2 1.0"/>
      </material>
    </visual>
  </link>
  <link name="right_f0_1">
    <origin rpy="0 0 0" xyz="0 0 0"/>
    <inertial>
      <mass value="0.033"/>
      <!-- F2 -->
      <origin xyz="0 0 0"/>
      <!-- solid cylinder -->
      <inertia ixx="0.00000165" ixy="0" ixz="0" iyy="0.00001316975" iyz="0" izz="0.00001316975"/>
    </inertial>
    <collision>
      <origin rpy="0 0 0" xyz="0 0 0"/>
      <geometry>
        <mesh filename="package://atlas_description/meshes_nv/sandia/f1.stl"/>
      </geometry>
    </collision>
    <visual>
      <origin rpy="0 0 0" xyz="0 0 0"/>
      <geometry>
        <mesh filename="package://atlas_description/meshes_nv/sandia/f1.stl"/>
      </geometry>
      <material name="right_sandia_hand_skin">
        <color rgba="0.835 0.655 0.345 1.0"/>
      </material>
    </visual>
  </link>
  <link name="right_f0_1_accel">
    <origin rpy="0 0 0" xyz="0 0 0"/>
    <inertial>
      <mass value="0.01"/>
      <origin xyz="0 0 0"/>
      <inertia ixx="0.000001" ixy="0" ixz="0" iyy="0.000001" iyz="0" izz="0.000001"/>
    </inertial>
  </link>
  <link name="right_f0_2">
    <origin rpy="0 0 0" xyz="0 0 0"/>
    <inertial>
      <mass value="0.033"/>
      <!-- F3 -->
      <origin xyz="0 0 0"/>
      <!-- solid cylinder -->
      <inertia ixx="0.0000013365" ixy="0" ixz="0" iyy="0.000009603" iyz="0" izz="0.000009603"/>
    </inertial>
    <collision>
      <origin rpy="0 0 0" xyz="0 0 0"/>
      <geometry>
        <mesh filename="package://atlas_description/meshes_nv/sandia/f2.stl"/>
      </geometry>
    </collision>
    <visual>
      <origin rpy="0 0 0" xyz="0 0 0"/>
      <geometry>
        <mesh filename="package://atlas_description/meshes_nv/sandia/f2.stl"/>
      </geometry>
      <material name="right_sandia_hand_skin_suntan">
        <color rgba="0.8 0.6 0.3 1.0"/>
      </material>
    </visual>
  </link>
  <link name="right_f0_2_accel">
    <origin rpy="0 0 0" xyz="0 0 0"/>
    <inertial>
      <mass value="0.01"/>
      <origin xyz="0 0 0"/>
      <inertia ixx="0.000001" ixy="0" ixz="0" iyy="0.000001" iyz="0" izz="0.000001"/>
    </inertial>
  </link>
  <joint name="right_f0_base" type="fixed">
    <parent link="right_palm"/>
    <child link="right_f0_base"/>
    <origin rpy="0 0 -0.3" xyz="0.14 0.0 0"/>
  </joint>
  <joint name="right_f0_j0" type="revolute">
    <axis xyz="0 0 -1"/>
    <parent link="right_f0_base"/>
    <child link="right_f0_0"/>
    <limit effort="11" lower="-1.57079632679" upper="1.57079632679" velocity="-1"/>
    <safety_controller k_position="1000.0" k_velocity="1000.0" soft_lower_limit="-11.57079" soft_upper_limit="11.57079"/>
    <dynamics damping="1.0"/>
    <origin rpy="0 0 0" xyz="0 0 0"/>
  </joint>
  <joint name="right_f0_j1" type="revolute">
    <axis xyz="0 0 1"/>
    <parent link="right_f0_0"/>
    <child link="right_f0_1"/>
    <limit effort="28" lower="-1.57079632679" upper="1.57079632679" velocity="-1"/>
    <safety_controller k_position="1000.0" k_velocity="1000.0" soft_lower_limit="-11.57079" soft_upper_limit="11.57079"/>
    <dynamics damping="1.0"/>
    <origin rpy="1.57079632679 0 0" xyz="0.028 0 0"/>
  </joint>
  <joint name="right_f0_j2" type="revolute">
    <axis xyz="0 0 1"/>
    <parent link="right_f0_1"/>
    <child link="right_f0_2"/>
    <origin rpy="0 0 0" xyz="0.05 0 0"/>
    <safety_controller k_position="1000.0" k_velocity="1000.0" soft_lower_limit="-11.57079" soft_upper_limit="11.57079"/>
    <dynamics damping="1.0"/>
    <limit effort="28" lower="-1.57079632679" upper="1.57079632679" velocity="-1"/>
  </joint>
  <joint name="right_f0_fixed_accel" type="fixed">
    <parent link="right_f0_base"/>
    <child link="right_f0_fixed_accel"/>
    <origin rpy="0 0 0" xyz="-0.05 0 0"/>
  </joint>
  <joint name="right_f0_1_accel" type="fixed">
    <parent link="right_f0_1"/>
    <child link="right_f0_1_accel"/>
    <origin rpy="-1.57079632679 0 0" xyz="0.03 0 0"/>
  </joint>
  <joint name="right_f0_2_accel" type="fixed">
    <parent link="right_f0_2"/>
    <child link="right_f0_2_accel"/>
    <origin rpy="-1.57079632679 0 0" xyz="0.04 0 0"/>
  </joint>

  <link name="right_f1_base">
    <origin rpy="0 0 0" xyz="0 0 0"/>
    <inertial>
      <!-- total mass is 2.303 kg, palm is about 1.303 kg, distribute the rest into _base -->
      <mass value="0.250"/>
      <!-- (2.303 - 1.303) / 4 -->
      <origin xyz="0 0 0"/>
      <!-- model as sphere with radius of 1cm -->
      <inertia ixx="0.00001" ixy="0" ixz="0" iyy="0.00001" iyz="0" izz="0.00001"/>
    </inertial>
  </link>
  <link name="right_f1_fixed_accel">
    <origin rpy="0 0 0" xyz="0 0 0"/>
    <inertial>
      <mass value="0.01"/>
      <origin xyz="0 0 0"/>
      <inertia ixx="0.000001" ixy="0" ixz="0" iyy="0.000001" iyz="0" izz="0.000001"/>
    </inertial>
  </link>
  <link name="right_f1_0">
    <origin rpy="0 0 0" xyz="0 0 0"/>
    <inertial>
      <mass value="0.106"/>
      <!-- F1 -->
      <origin xyz="0 0 0"/>
      <!-- solid cylinder -->
      <inertia ixx="0.000011925" ixy="0" ixz="0" iyy="0.00011505" iyz="0" izz="0.00011505"/>
    </inertial>
    <collision>
      <origin rpy="0 0 0" xyz="0 0 0"/>
      <geometry>
        <mesh filename="package://atlas_description/meshes_nv/sandia/f0.stl"/>
      </geometry>
    </collision>
    <visual>
      <origin rpy="0 0 0" xyz="0 0 0"/>
      <geometry>
        <mesh filename="package://atlas_description/meshes_nv/sandia/f0.stl"/>
      </geometry>
      <material name="right_sandia_hand_skin_suntan">
        <color rgba="0.7 0.4 0.2 1.0"/>
      </material>
    </visual>
  </link>
  <link name="right_f1_1">
    <origin rpy="0 0 0" xyz="0 0 0"/>
    <inertial>
      <mass value="0.033"/>
      <!-- F2 -->
      <origin xyz="0 0 0"/>
      <!-- solid cylinder -->
      <inertia ixx="0.00000165" ixy="0" ixz="0" iyy="0.00001316975" iyz="0" izz="0.00001316975"/>
    </inertial>
    <collision>
      <origin rpy="0 0 0" xyz="0 0 0"/>
      <geometry>
        <mesh filename="package://atlas_description/meshes_nv/sandia/f1.stl"/>
      </geometry>
    </collision>
    <visual>
      <origin rpy="0 0 0" xyz="0 0 0"/>
      <geometry>
        <mesh filename="package://atlas_description/meshes_nv/sandia/f1.stl"/>
      </geometry>
      <material name="right_sandia_hand_skin">
        <color rgba="0.835 0.655 0.345 1.0"/>
      </material>
    </visual>
  </link>
  <link name="right_f1_1_accel">
    <origin rpy="0 0 0" xyz="0 0 0"/>
    <inertial>
      <mass value="0.01"/>
      <origin xyz="0 0 0"/>
      <inertia ixx="0.000001" ixy="0" ixz="0" iyy="0.000001" iyz="0" izz="0.000001"/>
    </inertial>
  </link>
  <link name="right_f1_2">
    <origin rpy="0 0 0" xyz="0 0 0"/>
    <inertial>
      <mass value="0.033"/>
      <!-- F3 -->
      <origin xyz="0 0 0"/>
      <!-- solid cylinder -->
      <inertia ixx="0.0000013365" ixy="0" ixz="0" iyy="0.000009603" iyz="0" izz="0.000009603"/>
    </inertial>
    <collision>
      <origin rpy="0 0 0" xyz="0 0 0"/>
      <geometry>
        <mesh filename="package://atlas_description/meshes_nv/sandia/f2.stl"/>
      </geometry>
    </collision>
    <visual>
      <origin rpy="0 0 0" xyz="0 0 0"/>
      <geometry>
        <mesh filename="package://atlas_description/meshes_nv/sandia/f2.stl"/>
      </geometry>
      <material name="right_sandia_hand_skin_suntan">
        <color rgba="0.8 0.6 0.3 1.0"/>
      </material>
    </visual>
  </link>
  <link name="right_f1_2_accel">
    <origin rpy="0 0 0" xyz="0 0 0"/>
    <inertial>
      <mass value="0.01"/>
      <origin xyz="0 0 0"/>
      <inertia ixx="0.000001" ixy="0" ixz="0" iyy="0.000001" iyz="0" izz="0.000001"/>
    </inertial>
  </link>
  <joint name="right_f1_base" type="fixed">
    <parent link="right_palm"/>
    <child link="right_f1_base"/>
    <origin rpy="0 0 -0.3" xyz="0.115 -0.03122 0"/>
  </joint>
  <joint name="right_f1_j0" type="revolute">
    <axis xyz="0 0 -1"/>
    <parent link="right_f1_base"/>
    <child link="right_f1_0"/>
    <limit effort="11" lower="-1.57079632679" upper="1.57079632679" velocity="-1"/>
    <safety_controller k_position="1000.0" k_velocity="1000.0" soft_lower_limit="-11.57079" soft_upper_limit="11.57079"/>
    <dynamics damping="1.0"/>
    <origin rpy="0 0 0" xyz="0 0 0"/>
  </joint>
  <joint name="right_f1_j1" type="revolute">
    <axis xyz="0 0 1"/>
    <parent link="right_f1_0"/>
    <child link="right_f1_1"/>
    <limit effort="28" lower="-1.57079632679" upper="1.57079632679" velocity="-1"/>
    <safety_controller k_position="1000.0" k_velocity="1000.0" soft_lower_limit="-11.57079" soft_upper_limit="11.57079"/>
    <dynamics damping="1.0"/>
    <origin rpy="1.57079632679 0 0" xyz="0.028 0 0"/>
  </joint>
  <joint name="right_f1_j2" type="revolute">
    <axis xyz="0 0 1"/>
    <parent link="right_f1_1"/>
    <child link="right_f1_2"/>
    <origin rpy="0 0 0" xyz="0.05 0 0"/>
    <safety_controller k_position="1000.0" k_velocity="1000.0" soft_lower_limit="-11.57079" soft_upper_limit="11.57079"/>
    <dynamics damping="1.0"/>
    <limit effort="28" lower="-1.57079632679" upper="1.57079632679" velocity="-1"/>
  </joint>
  <joint name="right_f1_fixed_accel" type="fixed">
    <parent link="right_f1_base"/>
    <child link="right_f1_fixed_accel"/>
    <origin rpy="0 0 0" xyz="-0.05 0 0"/>
  </joint>
  <joint name="right_f1_1_accel" type="fixed">
    <parent link="right_f1_1"/>
    <child link="right_f1_1_accel"/>
    <origin rpy="-1.57079632679 0 0" xyz="0.03 0 0"/>
  </joint>
  <joint name="right_f1_2_accel" type="fixed">
    <parent link="right_f1_2"/>
    <child link="right_f1_2_accel"/>
    <origin rpy="-1.57079632679 0 0" xyz="0.04 0 0"/>
  </joint>
  
  <link name="right_f2_base">
    <origin rpy="0 0 0" xyz="0 0 0"/>
    <inertial>
      <!-- total mass is 2.303 kg, palm is about 1.303 kg, distribute the rest into _base -->
      <mass value="0.250"/>
      <!-- (2.303 - 1.303) / 4 -->
      <origin xyz="0 0 0"/>
      <!-- model as sphere with radius of 1cm -->
      <inertia ixx="0.00001" ixy="0" ixz="0" iyy="0.00001" iyz="0" izz="0.00001"/>
    </inertial>
  </link>
  <link name="right_f2_fixed_accel">
    <origin rpy="0 0 0" xyz="0 0 0"/>
    <inertial>
      <mass value="0.01"/>
      <origin xyz="0 0 0"/>
      <inertia ixx="0.000001" ixy="0" ixz="0" iyy="0.000001" iyz="0" izz="0.000001"/>
    </inertial>
  </link>
  <link name="right_f2_0">
    <origin rpy="0 0 0" xyz="0 0 0"/>
    <inertial>
      <mass value="0.106"/>
      <!-- F1 -->
      <origin xyz="0 0 0"/>
      <!-- solid cylinder -->
      <inertia ixx="0.000011925" ixy="0" ixz="0" iyy="0.00011505" iyz="0" izz="0.00011505"/>
    </inertial>
    <collision>
      <origin rpy="0 0 0" xyz="0 0 0"/>
      <geometry>
        <mesh filename="package://atlas_description/meshes_nv/sandia/f0.stl"/>
      </geometry>
    </collision>
    <visual>
      <origin rpy="0 0 0" xyz="0 0 0"/>
      <geometry>
        <mesh filename="package://atlas_description/meshes_nv/sandia/f0.stl"/>
      </geometry>
      <material name="right_sandia_hand_skin_suntan">
        <color rgba="0.7 0.4 0.2 1.0"/>
      </material>
    </visual>
  </link>
  <link name="right_f2_1">
    <origin rpy="0 0 0" xyz="0 0 0"/>
    <inertial>
      <mass value="0.033"/>
      <!-- F2 -->
      <origin xyz="0 0 0"/>
      <!-- solid cylinder -->
      <inertia ixx="0.00000165" ixy="0" ixz="0" iyy="0.00001316975" iyz="0" izz="0.00001316975"/>
    </inertial>
    <collision>
      <origin rpy="0 0 0" xyz="0 0 0"/>
      <geometry>
        <mesh filename="package://atlas_description/meshes_nv/sandia/f1.stl"/>
      </geometry>
    </collision>
    <visual>
      <origin rpy="0 0 0" xyz="0 0 0"/>
      <geometry>
        <mesh filename="package://atlas_description/meshes_nv/sandia/f1.stl"/>
      </geometry>
      <material name="right_sandia_hand_skin">
        <color rgba="0.835 0.655 0.345 1.0"/>
      </material>
    </visual>
  </link>
  <link name="right_f2_1_accel">
    <origin rpy="0 0 0" xyz="0 0 0"/>
    <inertial>
      <mass value="0.01"/>
      <origin xyz="0 0 0"/>
      <inertia ixx="0.000001" ixy="0" ixz="0" iyy="0.000001" iyz="0" izz="0.000001"/>
    </inertial>
  </link>
  <link name="right_f2_2">
    <origin rpy="0 0 0" xyz="0 0 0"/>
    <inertial>
      <mass value="0.033"/>
      <!-- F3 -->
      <origin xyz="0 0 0"/>
      <!-- solid cylinder -->
      <inertia ixx="0.0000013365" ixy="0" ixz="0" iyy="0.000009603" iyz="0" izz="0.000009603"/>
    </inertial>
    <collision>
      <origin rpy="0 0 0" xyz="0 0 0"/>
      <geometry>
        <mesh filename="package://atlas_description/meshes_nv/sandia/f2.stl"/>
      </geometry>
    </collision>
    <visual>
      <origin rpy="0 0 0" xyz="0 0 0"/>
      <geometry>
        <mesh filename="package://atlas_description/meshes_nv/sandia/f2.stl"/>
      </geometry>
      <material name="right_sandia_hand_skin_suntan">
        <color rgba="0.8 0.6 0.3 1.0"/>
      </material>
    </visual>
  </link>
  <link name="right_f2_2_accel">
    <origin rpy="0 0 0" xyz="0 0 0"/>
    <inertial>
      <mass value="0.01"/>
      <origin xyz="0 0 0"/>
      <inertia ixx="0.000001" ixy="0" ixz="0" iyy="0.000001" iyz="0" izz="0.000001"/>
    </inertial>
  </link>
  <joint name="right_f2_base" type="fixed">
    <parent link="right_palm"/>
    <child link="right_f2_base"/>
    <origin rpy="0 0 -0.3" xyz="0.09 -0.06245 0"/>
  </joint>
  <joint name="right_f2_j0" type="revolute">
    <axis xyz="0 0 -1"/>
    <parent link="right_f2_base"/>
    <child link="right_f2_0"/>
    <limit effort="11" lower="-1.57079632679" upper="1.57079632679" velocity="-1"/>
    <safety_controller k_position="1000.0" k_velocity="1000.0" soft_lower_limit="-11.57079" soft_upper_limit="11.57079"/>
    <dynamics damping="1.0"/>
    <origin rpy="0 0 0" xyz="0 0 0"/>
  </joint>
  <joint name="right_f2_j1" type="revolute">
    <axis xyz="0 0 1"/>
    <parent link="right_f2_0"/>
    <child link="right_f2_1"/>
    <limit effort="28" lower="-1.57079632679" upper="1.57079632679" velocity="-1"/>
    <safety_controller k_position="1000.0" k_velocity="1000.0" soft_lower_limit="-11.57079" soft_upper_limit="11.57079"/>
    <dynamics damping="1.0"/>
    <origin rpy="1.57079632679 0 0" xyz="0.028 0 0"/>
  </joint>
  <joint name="right_f2_j2" type="revolute">
    <axis xyz="0 0 1"/>
    <parent link="right_f2_1"/>
    <child link="right_f2_2"/>
    <origin rpy="0 0 0" xyz="0.05 0 0"/>
    <safety_controller k_position="1000.0" k_velocity="1000.0" soft_lower_limit="-11.57079" soft_upper_limit="11.57079"/>
    <dynamics damping="1.0"/>
    <limit effort="28" lower="-1.57079632679" upper="1.57079632679" velocity="-1"/>
  </joint>
  <joint name="right_f2_fixed_accel" type="fixed">
    <parent link="right_f2_base"/>
    <child link="right_f2_fixed_accel"/>
    <origin rpy="0 0 0" xyz="-0.05 0 0"/>
  </joint>
  <joint name="right_f2_1_accel" type="fixed">
    <parent link="right_f2_1"/>
    <child link="right_f2_1_accel"/>
    <origin rpy="-1.57079632679 0 0" xyz="0.03 0 0"/>
  </joint>
  <joint name="right_f2_2_accel" type="fixed">
    <parent link="right_f2_2"/>
    <child link="right_f2_2_accel"/>
    <origin rpy="-1.57079632679 0 0" xyz="0.04 0 0"/>
  </joint>
  
  <link name="right_f3_base">
    <origin rpy="0 0 0" xyz="0 0 0"/>
    <inertial>
      <!-- total mass is 2.303 kg, palm is about 1.303 kg, distribute the rest into _base -->
      <mass value="0.250"/>
      <!-- (2.303 - 1.303) / 4 -->
      <origin xyz="0 0 0"/>
      <!-- model as sphere with radius of 1cm -->
      <inertia ixx="0.00001" ixy="0" ixz="0" iyy="0.00001" iyz="0" izz="0.00001"/>
    </inertial>
  </link>
  <link name="right_f3_fixed_accel">
    <origin rpy="0 0 0" xyz="0 0 0"/>
    <inertial>
      <mass value="0.01"/>
      <origin xyz="0 0 0"/>
      <inertia ixx="0.000001" ixy="0" ixz="0" iyy="0.000001" iyz="0" izz="0.000001"/>
    </inertial>
  </link>
  <link name="right_f3_0">
    <origin rpy="0 0 0" xyz="0 0 0"/>
    <inertial>
      <mass value="0.106"/>
      <!-- F1 -->
      <origin xyz="0 0 0"/>
      <!-- solid cylinder -->
      <inertia ixx="0.000011925" ixy="0" ixz="0" iyy="0.00011505" iyz="0" izz="0.00011505"/>
    </inertial>
    <collision>
      <origin rpy="0 0 0" xyz="0 0 0"/>
      <geometry>
        <mesh filename="package://atlas_description/meshes_nv/sandia/f0.stl"/>
      </geometry>
    </collision>
    <visual>
      <origin rpy="0 0 0" xyz="0 0 0"/>
      <geometry>
        <mesh filename="package://atlas_description/meshes_nv/sandia/f0.stl"/>
      </geometry>
      <material name="right_sandia_hand_skin_suntan">
        <color rgba="0.7 0.4 0.2 1.0"/>
      </material>
    </visual>
  </link>
  <link name="right_f3_1">
    <origin rpy="0 0 0" xyz="0 0 0"/>
    <inertial>
      <mass value="0.033"/>
      <!-- F2 -->
      <origin xyz="0 0 0"/>
      <!-- solid cylinder -->
      <inertia ixx="0.00000165" ixy="0" ixz="0" iyy="0.00001316975" iyz="0" izz="0.00001316975"/>
    </inertial>
    <collision>
      <origin rpy="0 0 0" xyz="0 0 0"/>
      <geometry>
        <mesh filename="package://atlas_description/meshes_nv/sandia/f1.stl"/>
      </geometry>
    </collision>
    <visual>
      <origin rpy="0 0 0" xyz="0 0 0"/>
      <geometry>
        <mesh filename="package://atlas_description/meshes_nv/sandia/f1.stl"/>
      </geometry>
      <material name="right_sandia_hand_skin">
        <color rgba="0.835 0.655 0.345 1.0"/>
      </material>
    </visual>
  </link>
  <link name="right_f3_1_accel">
    <origin rpy="0 0 0" xyz="0 0 0"/>
    <inertial>
      <mass value="0.01"/>
      <origin xyz="0 0 0"/>
      <inertia ixx="0.000001" ixy="0" ixz="0" iyy="0.000001" iyz="0" izz="0.000001"/>
    </inertial>
  </link>
  <link name="right_f3_2">
    <origin rpy="0 0 0" xyz="0 0 0"/>
    <inertial>
      <mass value="0.033"/>
      <!-- F3 -->
      <origin xyz="0 0 0"/>
      <!-- solid cylinder -->
      <inertia ixx="0.0000013365" ixy="0" ixz="0" iyy="0.000009603" iyz="0" izz="0.000009603"/>
    </inertial>
    <collision>
      <origin rpy="0 0 0" xyz="0 0 0"/>
      <geometry>
        <mesh filename="package://atlas_description/meshes_nv/sandia/f2.stl"/>
      </geometry>
    </collision>
    <visual>
      <origin rpy="0 0 0" xyz="0 0 0"/>
      <geometry>
        <mesh filename="package://atlas_description/meshes_nv/sandia/f2.stl"/>
      </geometry>
      <material name="right_sandia_hand_skin_suntan">
        <color rgba="0.8 0.6 0.3 1.0"/>
      </material>
    </visual>
  </link>
  <link name="right_f3_2_accel">
    <origin rpy="0 0 0" xyz="0 0 0"/>
    <inertial>
      <mass value="0.01"/>
      <origin xyz="0 0 0"/>
      <inertia ixx="0.000001" ixy="0" ixz="0" iyy="0.000001" iyz="0" izz="0.000001"/>
    </inertial>
  </link>
  <joint name="right_f3_base" type="fixed">
    <parent link="right_palm"/>
    <child link="right_f3_base"/>
    <origin rpy="0 -1.57079632679 2.3562" xyz="0.03995 0.04383 0.014"/>
  </joint>
  <joint name="right_f3_j0" type="revolute">
    <axis xyz="0 0 -1"/>
    <parent link="right_f3_base"/>
    <child link="right_f3_0"/>
    <limit effort="11" lower="-1.57079632679" upper="1.57079632679" velocity="-1"/>
    <safety_controller k_position="1000.0" k_velocity="1000.0" soft_lower_limit="-11.57079" soft_upper_limit="11.57079"/>
    <dynamics damping="1.0"/>
    <origin rpy="0 0 0" xyz="0 0 0"/>
  </joint>
  <joint name="right_f3_j1" type="revolute">
    <axis xyz="0 0 1"/>
    <parent link="right_f3_0"/>
    <child link="right_f3_1"/>
    <limit effort="28" lower="-1.57079632679" upper="1.57079632679" velocity="-1"/>
    <safety_controller k_position="1000.0" k_velocity="1000.0" soft_lower_limit="-11.57079" soft_upper_limit="11.57079"/>
    <dynamics damping="1.0"/>
    <origin rpy="1.57079632679 0 0" xyz="0.028 0 0"/>
  </joint>
  <joint name="right_f3_j2" type="revolute">
    <axis xyz="0 0 1"/>
    <parent link="right_f3_1"/>
    <child link="right_f3_2"/>
    <origin rpy="0 0 0" xyz="0.05 0 0"/>
    <safety_controller k_position="1000.0" k_velocity="1000.0" soft_lower_limit="-11.57079" soft_upper_limit="11.57079"/>
    <dynamics damping="1.0"/>
    <limit effort="28" lower="-1.57079632679" upper="1.57079632679" velocity="-1"/>
  </joint>
  <joint name="right_f3_fixed_accel" type="fixed">
    <parent link="right_f3_base"/>
    <child link="right_f3_fixed_accel"/>
    <origin rpy="0 0 0" xyz="-0.05 0 0"/>
  </joint>
  <joint name="right_f3_1_accel" type="fixed">
    <parent link="right_f3_1"/>
    <child link="right_f3_1_accel"/>
    <origin rpy="-1.57079632679 0 0" xyz="0.03 0 0"/>
  </joint>
  <joint name="right_f3_2_accel" type="fixed">
    <parent link="right_f3_2"/>
    <child link="right_f3_2_accel"/>
    <origin rpy="-1.57079632679 0 0" xyz="0.04 0 0"/>
  </joint>
  
  <joint name="right_palm_left_camera_frame_joint" type="fixed">
    <origin rpy="-0.6708 -1.57079632679 3.14159265359" xyz="0.0435128991906 -0.0451672761576 0.025"/>
    <parent link="right_palm"/>
    <child link="right_palm_left_camera_frame"/>
  </joint>
  <link name="right_palm_left_camera_frame">
    <inertial>
      <mass value="0.01"/>
      <origin xyz="0 0 0"/>
      <inertia ixx="0.0001" ixy="0.0" ixz="0.0" iyy="0.0001" iyz="0.0" izz="0.0001"/>
    </inertial>
    <visual group="default">
      <origin rpy="0 0 0" xyz="0 0 0"/>
      <geometry>
        <box size="0.003 0.010 0.007"/>
      </geometry>
    </visual>
  </link>
  <joint name="right_palm_left_camera_optical_frame_joint" type="fixed">
    <origin rpy="-1.57079632679 0.0 -1.57079632679" xyz="0 0 0"/>
    <parent link="right_palm_left_camera_frame"/>
    <child link="right_palm_left_camera_optical_frame"/>
  </joint>
  <link name="right_palm_left_camera_optical_frame"/>
 
  <joint name="right_palm_right_camera_frame_joint" type="fixed">
    <origin rpy="-0.6708 -1.57079632679 3.14159265359" xyz="0.0683774130138 -0.0138342911048 0.025"/>
    <parent link="right_palm"/>
    <child link="right_palm_right_camera_frame"/>
  </joint>
  <link name="right_palm_right_camera_frame">
    <inertial>
      <mass value="0.01"/>
      <origin xyz="0 0 0"/>
      <inertia ixx="0.0001" ixy="0.0" ixz="0.0" iyy="0.0001" iyz="0.0" izz="0.0001"/>
    </inertial>
    <visual group="default">
      <origin rpy="0 0 0" xyz="0 0 0"/>
      <geometry>
        <box size="0.003 0.010 0.007"/>
      </geometry>
    </visual>
  </link>

</robot>

